2020-09-05 13:56:55,600 p=19152 u=ganti n=ansible | [DEPRECATION WARNING]: The TRANSFORM_INVALID_GROUP_CHARS settings is set to allow bad characters in group names by default, this will change, but still be user 
configurable on deprecation. This feature will be removed in version 2.10. Deprecation warnings can be disabled by setting deprecation_warnings=False in 
ansible.cfg.
2020-09-05 13:56:55,601 p=19152 u=ganti n=ansible | [WARNING]: Invalid characters were found in group names but not replaced, use -vvvv to see details

2020-09-05 13:56:56,226 p=19152 u=ganti n=ansible | ERROR! 'bigip_device_info' is not a valid attribute for a Play

The error appears to be in '/Users/ganti/Code/ansible-tower/app.yml': line 8, column 3, but may
be elsewhere in the file depending on the exact syntax problem.

The offending line appears to be:


- name: Collect BIG-IP information
  ^ here

2020-09-05 15:08:33,248 p=35463 u=ganti n=ansible | [DEPRECATION WARNING]: The TRANSFORM_INVALID_GROUP_CHARS settings is set to allow bad 
characters in group names by default, this will change, but still be user configurable on 
deprecation. This feature will be removed in version 2.10. Deprecation warnings can be 
disabled by setting deprecation_warnings=False in ansible.cfg.
2020-09-05 15:08:33,249 p=35463 u=ganti n=ansible | [WARNING]: Invalid characters were found in group names but not replaced, use -vvvv to see
details

2020-09-05 15:08:33,923 p=35463 u=ganti n=ansible | PLAY [Big IP Operations] **********************************************************************
2020-09-05 15:08:33,961 p=35463 u=ganti n=ansible | TASK [device-info : include_tasks] ************************************************************
2020-09-05 15:08:33,961 p=35463 u=ganti n=ansible | Saturday 05 September 2020  15:08:33 -0400 (0:00:00.066)       0:00:00.066 **** 
2020-09-05 15:08:34,386 p=35463 u=ganti n=ansible | included: /Users/ganti/Code/ansible-tower/roles/device-info/tasks/devices.yml for localhost
2020-09-05 15:08:34,398 p=35463 u=ganti n=ansible | TASK [device-info : COLLECT BIG-IP Devices] ***************************************************
2020-09-05 15:08:34,398 p=35463 u=ganti n=ansible | Saturday 05 September 2020  15:08:34 -0400 (0:00:00.437)       0:00:00.503 **** 
2020-09-05 15:08:36,103 p=35463 u=ganti n=ansible | An exception occurred during task execution. To see the full traceback, use -vvv. The error was: urllib.error.URLError: <urlopen error [Errno 61] Connection refused>
2020-09-05 15:08:36,147 p=35463 u=ganti n=ansible | fatal: [localhost -> localhost]: FAILED! => {"changed": false, "module_stderr": "Traceback (most recent call last):\n  File \"/usr/local/Cellar/python/3.7.4_1/Frameworks/Python.framework/Versions/3.7/lib/python3.7/urllib/request.py\", line 1317, in do_open\n    encode_chunked=req.has_header('Transfer-encoding'))\n  File \"/usr/local/Cellar/python/3.7.4_1/Frameworks/Python.framework/Versions/3.7/lib/python3.7/http/client.py\", line 1244, in request\n    self._send_request(method, url, body, headers, encode_chunked)\n  File \"/usr/local/Cellar/python/3.7.4_1/Frameworks/Python.framework/Versions/3.7/lib/python3.7/http/client.py\", line 1290, in _send_request\n    self.endheaders(body, encode_chunked=encode_chunked)\n  File \"/usr/local/Cellar/python/3.7.4_1/Frameworks/Python.framework/Versions/3.7/lib/python3.7/http/client.py\", line 1239, in endheaders\n    self._send_output(message_body, encode_chunked=encode_chunked)\n  File \"/usr/local/Cellar/python/3.7.4_1/Frameworks/Python.framework/Versions/3.7/lib/python3.7/http/client.py\", line 1026, in _send_output\n    self.send(msg)\n  File \"/usr/local/Cellar/python/3.7.4_1/Frameworks/Python.framework/Versions/3.7/lib/python3.7/http/client.py\", line 966, in send\n    self.connect()\n  File \"/usr/local/Cellar/python/3.7.4_1/Frameworks/Python.framework/Versions/3.7/lib/python3.7/http/client.py\", line 1406, in connect\n    super().connect()\n  File \"/usr/local/Cellar/python/3.7.4_1/Frameworks/Python.framework/Versions/3.7/lib/python3.7/http/client.py\", line 938, in connect\n    (self.host,self.port), self.timeout, self.source_address)\n  File \"/usr/local/Cellar/python/3.7.4_1/Frameworks/Python.framework/Versions/3.7/lib/python3.7/socket.py\", line 727, in create_connection\n    raise err\n  File \"/usr/local/Cellar/python/3.7.4_1/Frameworks/Python.framework/Versions/3.7/lib/python3.7/socket.py\", line 716, in create_connection\n    sock.connect(sa)\nConnectionRefusedError: [Errno 61] Connection refused\n\nDuring handling of the above exception, another exception occurred:\n\nTraceback (most recent call last):\n  File \"<stdin>\", line 102, in <module>\n  File \"<stdin>\", line 94, in _ansiballz_main\n  File \"<stdin>\", line 40, in invoke_module\n  File \"/usr/local/Cellar/python/3.7.4_1/Frameworks/Python.framework/Versions/3.7/lib/python3.7/runpy.py\", line 205, in run_module\n    return _run_module_code(code, init_globals, run_name, mod_spec)\n  File \"/usr/local/Cellar/python/3.7.4_1/Frameworks/Python.framework/Versions/3.7/lib/python3.7/runpy.py\", line 96, in _run_module_code\n    mod_name, mod_spec, pkg_name, script_name)\n  File \"/usr/local/Cellar/python/3.7.4_1/Frameworks/Python.framework/Versions/3.7/lib/python3.7/runpy.py\", line 85, in _run_code\n    exec(code, run_globals)\n  File \"/var/folders/94/gcvyc1g9191_npwtrl55hsq54jxlgs/T/ansible_bigip_device_info_payload_xn1yght4/ansible_bigip_device_info_payload.zip/ansible/modules/network/f5/bigip_device_info.py\", line 16266, in <module>\n  File \"/var/folders/94/gcvyc1g9191_npwtrl55hsq54jxlgs/T/ansible_bigip_device_info_payload_xn1yght4/ansible_bigip_device_info_payload.zip/ansible/modules/network/f5/bigip_device_info.py\", line 16259, in main\n  File \"/var/folders/94/gcvyc1g9191_npwtrl55hsq54jxlgs/T/ansible_bigip_device_info_payload_xn1yght4/ansible_bigip_device_info_payload.zip/ansible/modules/network/f5/bigip_device_info.py\", line 15999, in exec_module\n  File \"/var/folders/94/gcvyc1g9191_npwtrl55hsq54jxlgs/T/ansible_bigip_device_info_payload_xn1yght4/ansible_bigip_device_info_payload.zip/ansible/modules/network/f5/bigip_device_info.py\", line 16075, in execute_managers\n  File \"/var/folders/94/gcvyc1g9191_npwtrl55hsq54jxlgs/T/ansible_bigip_device_info_payload_xn1yght4/ansible_bigip_device_info_payload.zip/ansible/module_utils/network/f5/icontrol.py\", line 598, in modules_provisioned\n  File \"/var/folders/94/gcvyc1g9191_npwtrl55hsq54jxlgs/T/ansible_bigip_device_info_payload_xn1yght4/ansible_bigip_device_info_payload.zip/ansible/module_utils/network/f5/bigip.py\", line 34, in api\n  File \"/var/folders/94/gcvyc1g9191_npwtrl55hsq54jxlgs/T/ansible_bigip_device_info_payload_xn1yght4/ansible_bigip_device_info_payload.zip/ansible/module_utils/network/f5/bigip.py\", line 58, in connect_via_token_auth\n  File \"/var/folders/94/gcvyc1g9191_npwtrl55hsq54jxlgs/T/ansible_bigip_device_info_payload_xn1yght4/ansible_bigip_device_info_payload.zip/ansible/module_utils/network/f5/icontrol.py\", line 238, in post\n  File \"/var/folders/94/gcvyc1g9191_npwtrl55hsq54jxlgs/T/ansible_bigip_device_info_payload_xn1yght4/ansible_bigip_device_info_payload.zip/ansible/module_utils/network/f5/icontrol.py\", line 193, in send\n  File \"/var/folders/94/gcvyc1g9191_npwtrl55hsq54jxlgs/T/ansible_bigip_device_info_payload_xn1yght4/ansible_bigip_device_info_payload.zip/ansible/module_utils/urls.py\", line 1294, in open\n  File \"/usr/local/Cellar/python/3.7.4_1/Frameworks/Python.framework/Versions/3.7/lib/python3.7/urllib/request.py\", line 222, in urlopen\n    return opener.open(url, data, timeout)\n  File \"/usr/local/Cellar/python/3.7.4_1/Frameworks/Python.framework/Versions/3.7/lib/python3.7/urllib/request.py\", line 525, in open\n    response = self._open(req, data)\n  File \"/usr/local/Cellar/python/3.7.4_1/Frameworks/Python.framework/Versions/3.7/lib/python3.7/urllib/request.py\", line 543, in _open\n    '_open', req)\n  File \"/usr/local/Cellar/python/3.7.4_1/Frameworks/Python.framework/Versions/3.7/lib/python3.7/urllib/request.py\", line 503, in _call_chain\n    result = func(*args)\n  File \"/var/folders/94/gcvyc1g9191_npwtrl55hsq54jxlgs/T/ansible_bigip_device_info_payload_xn1yght4/ansible_bigip_device_info_payload.zip/ansible/module_utils/urls.py\", line 467, in https_open\n  File \"/usr/local/Cellar/python/3.7.4_1/Frameworks/Python.framework/Versions/3.7/lib/python3.7/urllib/request.py\", line 1319, in do_open\n    raise URLError(err)\nurllib.error.URLError: <urlopen error [Errno 61] Connection refused>\n", "module_stdout": "", "msg": "MODULE FAILURE\nSee stdout/stderr for the exact error", "rc": 1}
2020-09-05 15:09:01,112 p=35463 u=ganti n=ansible | User interrupted execution
2020-09-05 15:09:02,823 p=35556 u=ganti n=ansible | [DEPRECATION WARNING]: The TRANSFORM_INVALID_GROUP_CHARS settings is set to allow bad characters in group 
names by default, this will change, but still be user configurable on deprecation. This feature will be 
removed in version 2.10. Deprecation warnings can be disabled by setting deprecation_warnings=False in 
ansible.cfg.
2020-09-05 15:09:02,824 p=35556 u=ganti n=ansible | [WARNING]: Invalid characters were found in group names but not replaced, use -vvvv to see details

2020-09-05 15:09:03,515 p=35556 u=ganti n=ansible | PLAY [Big IP Operations] **************************************************************************************
2020-09-05 15:09:03,546 p=35556 u=ganti n=ansible | TASK [device-info : include_tasks] ****************************************************************************
2020-09-05 15:09:03,546 p=35556 u=ganti n=ansible | Saturday 05 September 2020  15:09:03 -0400 (0:00:00.062)       0:00:00.062 **** 
2020-09-05 15:09:03,681 p=35556 u=ganti n=ansible | included: /Users/ganti/Code/ansible-tower/roles/device-info/tasks/devices.yml for localhost
2020-09-05 15:09:03,694 p=35556 u=ganti n=ansible | TASK [device-info : COLLECT BIG-IP Devices] *******************************************************************
2020-09-05 15:09:03,695 p=35556 u=ganti n=ansible | Saturday 05 September 2020  15:09:03 -0400 (0:00:00.148)       0:00:00.210 **** 
2020-09-05 15:09:06,856 p=35556 u=ganti n=ansible | ok: [localhost -> localhost]
2020-09-05 15:09:06,866 p=35556 u=ganti n=ansible | PLAY RECAP ****************************************************************************************************
2020-09-05 15:09:06,866 p=35556 u=ganti n=ansible | localhost                  : ok=2    changed=0    unreachable=0    failed=0    skipped=0    rescued=0    ignored=0   
2020-09-05 15:09:06,867 p=35556 u=ganti n=ansible | Saturday 05 September 2020  15:09:06 -0400 (0:00:03.171)       0:00:03.382 **** 
2020-09-05 15:09:06,867 p=35556 u=ganti n=ansible | =============================================================================== 
2020-09-05 15:09:06,867 p=35556 u=ganti n=ansible | device-info ------------------------------------------------------------- 3.32s
2020-09-05 15:09:06,867 p=35556 u=ganti n=ansible | ~~~~~~~~~~~~~~~~~~~~~~~~~~~~~~~~~~~~~~~~~~~~~~~~~~~~~~~~~~~~~~~~~~~~~~~~~~~~~~~ 
2020-09-05 15:09:06,867 p=35556 u=ganti n=ansible | total ------------------------------------------------------------------- 3.32s
2020-09-05 15:09:06,868 p=35556 u=ganti n=ansible | Playbook run took 0 days, 0 hours, 0 minutes, 3 seconds
2020-09-05 15:09:13,625 p=35615 u=ganti n=ansible | ansible-playbook 2.9.5
  config file = /Users/ganti/Code/ansible-tower/ansible.cfg
  configured module search path = ['/Users/ganti/.ansible/plugins/modules', '/usr/share/ansible/plugins/modules']
  ansible python module location = /usr/local/lib/python3.7/site-packages/ansible
  executable location = /usr/local/bin/ansible-playbook
  python version = 3.7.4 (default, Sep  7 2019, 18:27:02) [Clang 10.0.1 (clang-1001.0.46.4)]
2020-09-05 15:09:13,625 p=35615 u=ganti n=ansible | Using /Users/ganti/Code/ansible-tower/ansible.cfg as config file
2020-09-05 15:09:13,640 p=35615 u=ganti n=ansible | host_list declined parsing /Users/ganti/Code/ansible-tower/inventory/dev/hosts as it did not pass its verify_file() method
2020-09-05 15:09:13,641 p=35615 u=ganti n=ansible | script declined parsing /Users/ganti/Code/ansible-tower/inventory/dev/hosts as it did not pass its verify_file() method
2020-09-05 15:09:13,641 p=35615 u=ganti n=ansible | auto declined parsing /Users/ganti/Code/ansible-tower/inventory/dev/hosts as it did not pass its verify_file() method
2020-09-05 15:09:13,648 p=35615 u=ganti n=ansible | [DEPRECATION WARNING]: The TRANSFORM_INVALID_GROUP_CHARS settings is set to allow bad characters in group 
names by default, this will change, but still be user configurable on deprecation. This feature will be 
removed in version 2.10. Deprecation warnings can be disabled by setting deprecation_warnings=False in 
ansible.cfg.
2020-09-05 15:09:13,649 p=35615 u=ganti n=ansible | [WARNING]: Invalid characters were found in group names but not replaced, use -vvvv to see details

2020-09-05 15:09:13,665 p=35615 u=ganti n=ansible | Parsed /Users/ganti/Code/ansible-tower/inventory/dev/hosts inventory source with ini plugin
2020-09-05 15:09:14,251 p=35615 u=ganti n=ansible | PLAYBOOK: app.yml *********************************************************************************************
2020-09-05 15:09:14,251 p=35615 u=ganti n=ansible | 1 plays in app.yml
2020-09-05 15:09:14,255 p=35615 u=ganti n=ansible | PLAY [Big IP Operations] **************************************************************************************
2020-09-05 15:09:14,281 p=35615 u=ganti n=ansible | META: ran handlers
2020-09-05 15:09:14,298 p=35615 u=ganti n=ansible | TASK [device-info : include_tasks] ****************************************************************************
2020-09-05 15:09:14,298 p=35615 u=ganti n=ansible | task path: /Users/ganti/Code/ansible-tower/roles/device-info/tasks/main.yml:1
2020-09-05 15:09:14,299 p=35615 u=ganti n=ansible | Saturday 05 September 2020  15:09:14 -0400 (0:00:00.080)       0:00:00.080 **** 
2020-09-05 15:09:14,446 p=35615 u=ganti n=ansible | included: /Users/ganti/Code/ansible-tower/roles/device-info/tasks/devices.yml for localhost
2020-09-05 15:09:14,458 p=35615 u=ganti n=ansible | TASK [device-info : COLLECT BIG-IP Devices] *******************************************************************
2020-09-05 15:09:14,459 p=35615 u=ganti n=ansible | task path: /Users/ganti/Code/ansible-tower/roles/device-info/tasks/devices.yml:1
2020-09-05 15:09:14,459 p=35615 u=ganti n=ansible | Saturday 05 September 2020  15:09:14 -0400 (0:00:00.160)       0:00:00.241 **** 
2020-09-05 15:09:15,354 p=35627 u=ganti n=ansible | Using module file /usr/local/lib/python3.7/site-packages/ansible/modules/network/f5/bigip_device_info.py
2020-09-05 15:09:15,355 p=35627 u=ganti n=ansible | Pipelining is enabled.
2020-09-05 15:09:15,356 p=35627 u=ganti n=ansible | <localhost> ESTABLISH LOCAL CONNECTION FOR USER: ganti
2020-09-05 15:09:15,357 p=35627 u=ganti n=ansible | <localhost> EXEC /bin/sh -c '/usr/local/opt/python/bin/python3.7 && sleep 0'
2020-09-05 15:09:17,373 p=35615 u=ganti n=ansible | ok: [localhost -> localhost] => {
    "changed": false,
    "devices": [
        {
            "active_modules": [
                "Rate Shaping",
                "SSL, VE",
                "Anti-Virus Checks",
                "Machine Certificate Checks",
                "App Tunnel",
                "Remote Desktop",
                "APM, Limited",
                "Firewall Checks",
                "Application Acceleration Manager, Core",
                "Network Access",
                "Protected Workspace",
                "APM, Web Application",
                "Ram Cache",
                "Secure Virtual Keyboard",
                "Max Compression, VE",
                "Base Endpoint Security Checks",
                "IPV6 Gateway",
                "Recycle, BIG-IP, VE"
            ],
            "base_mac_address": "0e:b4:b8:0c:c7:0b",
            "build": "0.0.6",
            "chassis_id": "e6e82cec-dda4-df80-d62b16ad13e0",
            "chassis_type": "individual",
            "edition": "Point Release 4",
            "failover_state": "active",
            "full_path": "/Common/ip-172-31-192-90.ec2.internal",
            "hostname": "ip-172-31-192-90.ec2.internal",
            "management_address": "172.31.192.90",
            "marketing_name": "BIG-IP Virtual Edition",
            "multicast_address": "any6",
            "name": "ip-172-31-192-90.ec2.internal",
            "optional_modules": [
                "Acceleration Manager, AWS",
                "AFM, AWS",
                "APM, Base, AWS",
                "APM, Max CCU, AWS",
                "App Mode (TMSH Only, No Root/Bash)",
                "ASM, AWS",
                "DNS Services, AWS",
                "External Interface and Network HSM, VE",
                "Global Traffic Manager",
                "IP Intelligence, 1Yr, VE",
                "IP Intelligence, 3Yr, VE",
                "PSM, AWS",
                "Routing Bundle, AWS",
                "SDN Services, VE",
                "SSL, Forward Proxy, AWS",
                "WBA, AWS",
                "WOM, AWS"
            ],
            "platform_id": "Z100",
            "product": "BIG-IP",
            "self": "yes",
            "software_version": "15.1.0.4",
            "timezone": "UTC"
        }
    ],
    "invocation": {
        "module_args": {
            "gather_subset": [
                "devices"
            ],
            "provider": {
                "auth_provider": null,
                "password": "VALUE_SPECIFIED_IN_NO_LOG_PARAMETER",
                "server": "54.89.34.114",
                "server_port": 8443,
                "ssh_keyfile": null,
                "timeout": null,
                "transport": "rest",
                "user": "admin",
                "validate_certs": false
            }
        }
    },
    "queried": true
}
2020-09-05 15:09:17,378 p=35615 u=ganti n=ansible | META: ran handlers
2020-09-05 15:09:17,379 p=35615 u=ganti n=ansible | META: ran handlers
2020-09-05 15:09:17,383 p=35615 u=ganti n=ansible | PLAY RECAP ****************************************************************************************************
2020-09-05 15:09:17,383 p=35615 u=ganti n=ansible | localhost                  : ok=2    changed=0    unreachable=0    failed=0    skipped=0    rescued=0    ignored=0   
2020-09-05 15:09:17,384 p=35615 u=ganti n=ansible | Saturday 05 September 2020  15:09:17 -0400 (0:00:02.924)       0:00:03.165 **** 
2020-09-05 15:09:17,384 p=35615 u=ganti n=ansible | =============================================================================== 
2020-09-05 15:09:17,384 p=35615 u=ganti n=ansible | device-info ------------------------------------------------------------- 3.09s
2020-09-05 15:09:17,384 p=35615 u=ganti n=ansible | ~~~~~~~~~~~~~~~~~~~~~~~~~~~~~~~~~~~~~~~~~~~~~~~~~~~~~~~~~~~~~~~~~~~~~~~~~~~~~~~ 
2020-09-05 15:09:17,384 p=35615 u=ganti n=ansible | total ------------------------------------------------------------------- 3.09s
2020-09-05 15:09:17,385 p=35615 u=ganti n=ansible | Playbook run took 0 days, 0 hours, 0 minutes, 3 seconds
2020-09-08 21:14:03,518 p=88324 u=ganti n=ansible | ansible-playbook 2.9.5
  config file = /Users/ganti/Code/ansible-tower/ansible.cfg
  configured module search path = ['/Users/ganti/.ansible/plugins/modules', '/usr/share/ansible/plugins/modules']
  ansible python module location = /usr/local/lib/python3.7/site-packages/ansible
  executable location = /usr/local/bin/ansible-playbook
  python version = 3.7.4 (default, Sep  7 2019, 18:27:02) [Clang 10.0.1 (clang-1001.0.46.4)]
2020-09-08 21:14:03,519 p=88324 u=ganti n=ansible | Using /Users/ganti/Code/ansible-tower/ansible.cfg as config file
2020-09-08 21:14:03,532 p=88324 u=ganti n=ansible | host_list declined parsing /Users/ganti/Code/ansible-tower/inventory/dev/hosts as it did not pass its verify_file() method
2020-09-08 21:14:03,533 p=88324 u=ganti n=ansible | script declined parsing /Users/ganti/Code/ansible-tower/inventory/dev/hosts as it did not pass its verify_file() method
2020-09-08 21:14:03,533 p=88324 u=ganti n=ansible | auto declined parsing /Users/ganti/Code/ansible-tower/inventory/dev/hosts as it did not pass its verify_file() method
2020-09-08 21:14:03,537 p=88324 u=ganti n=ansible | [DEPRECATION WARNING]: The TRANSFORM_INVALID_GROUP_CHARS settings is set to allow bad characters in group names by default, this will change, but still be user 
configurable on deprecation. This feature will be removed in version 2.10. Deprecation warnings can be disabled by setting deprecation_warnings=False in 
ansible.cfg.
2020-09-08 21:14:03,537 p=88324 u=ganti n=ansible | [WARNING]: Invalid characters were found in group names but not replaced, use -vvvv to see details

2020-09-08 21:14:03,538 p=88324 u=ganti n=ansible | Parsed /Users/ganti/Code/ansible-tower/inventory/dev/hosts inventory source with ini plugin
2020-09-08 21:14:03,943 p=88324 u=ganti n=ansible | ERROR! 'role' is undefined
2020-09-08 21:14:36,086 p=88430 u=ganti n=ansible | ansible-playbook 2.9.5
  config file = /Users/ganti/Code/ansible-tower/ansible.cfg
  configured module search path = ['/Users/ganti/.ansible/plugins/modules', '/usr/share/ansible/plugins/modules']
  ansible python module location = /usr/local/lib/python3.7/site-packages/ansible
  executable location = /usr/local/bin/ansible-playbook
  python version = 3.7.4 (default, Sep  7 2019, 18:27:02) [Clang 10.0.1 (clang-1001.0.46.4)]
2020-09-08 21:14:36,087 p=88430 u=ganti n=ansible | Using /Users/ganti/Code/ansible-tower/ansible.cfg as config file
2020-09-08 21:14:36,095 p=88430 u=ganti n=ansible | host_list declined parsing /Users/ganti/Code/ansible-tower/inventory/dev/hosts as it did not pass its verify_file() method
2020-09-08 21:14:36,095 p=88430 u=ganti n=ansible | script declined parsing /Users/ganti/Code/ansible-tower/inventory/dev/hosts as it did not pass its verify_file() method
2020-09-08 21:14:36,095 p=88430 u=ganti n=ansible | auto declined parsing /Users/ganti/Code/ansible-tower/inventory/dev/hosts as it did not pass its verify_file() method
2020-09-08 21:14:36,099 p=88430 u=ganti n=ansible | [DEPRECATION WARNING]: The TRANSFORM_INVALID_GROUP_CHARS settings is set to allow bad characters in group names by default, this will change, but still be user 
configurable on deprecation. This feature will be removed in version 2.10. Deprecation warnings can be disabled by setting deprecation_warnings=False in 
ansible.cfg.
2020-09-08 21:14:36,099 p=88430 u=ganti n=ansible | [WARNING]: Invalid characters were found in group names but not replaced, use -vvvv to see details

2020-09-08 21:14:36,104 p=88430 u=ganti n=ansible | Parsed /Users/ganti/Code/ansible-tower/inventory/dev/hosts inventory source with ini plugin
2020-09-08 21:14:36,430 p=88430 u=ganti n=ansible | ERROR! the role 'ttcp' was not found in /Users/ganti/Code/ansible-tower/roles:/Users/ganti/Code/ansible-tower/roles:/Users/ganti/Code/ansible-tower

The error appears to be in '/Users/ganti/Code/ansible-tower/app.yml': line 11, column 7, but may
be elsewhere in the file depending on the exact syntax problem.

The offending line appears to be:

  roles:
    - "{{ role }}"
      ^ here
We could be wrong, but this one looks like it might be an issue with
missing quotes. Always quote template expression brackets when they
start a value. For instance:

    with_items:
      - {{ foo }}

Should be written as:

    with_items:
      - "{{ foo }}"

2020-09-08 21:14:42,753 p=88477 u=ganti n=ansible | ansible-playbook 2.9.5
  config file = /Users/ganti/Code/ansible-tower/ansible.cfg
  configured module search path = ['/Users/ganti/.ansible/plugins/modules', '/usr/share/ansible/plugins/modules']
  ansible python module location = /usr/local/lib/python3.7/site-packages/ansible
  executable location = /usr/local/bin/ansible-playbook
  python version = 3.7.4 (default, Sep  7 2019, 18:27:02) [Clang 10.0.1 (clang-1001.0.46.4)]
2020-09-08 21:14:42,753 p=88477 u=ganti n=ansible | Using /Users/ganti/Code/ansible-tower/ansible.cfg as config file
2020-09-08 21:14:42,760 p=88477 u=ganti n=ansible | host_list declined parsing /Users/ganti/Code/ansible-tower/inventory/dev/hosts as it did not pass its verify_file() method
2020-09-08 21:14:42,760 p=88477 u=ganti n=ansible | script declined parsing /Users/ganti/Code/ansible-tower/inventory/dev/hosts as it did not pass its verify_file() method
2020-09-08 21:14:42,760 p=88477 u=ganti n=ansible | auto declined parsing /Users/ganti/Code/ansible-tower/inventory/dev/hosts as it did not pass its verify_file() method
2020-09-08 21:14:42,763 p=88477 u=ganti n=ansible | [DEPRECATION WARNING]: The TRANSFORM_INVALID_GROUP_CHARS settings is set to allow bad characters in group names by default, this will change, but still be user 
configurable on deprecation. This feature will be removed in version 2.10. Deprecation warnings can be disabled by setting deprecation_warnings=False in 
ansible.cfg.
2020-09-08 21:14:42,763 p=88477 u=ganti n=ansible | [WARNING]: Invalid characters were found in group names but not replaced, use -vvvv to see details

2020-09-08 21:14:42,764 p=88477 u=ganti n=ansible | Parsed /Users/ganti/Code/ansible-tower/inventory/dev/hosts inventory source with ini plugin
2020-09-08 21:14:43,062 p=88477 u=ganti n=ansible | PLAYBOOK: app.yml ***********************************************************************************************************************************************
2020-09-08 21:14:43,063 p=88477 u=ganti n=ansible | 1 plays in app.yml
2020-09-08 21:14:43,064 p=88477 u=ganti n=ansible | PLAY [Big IP Operations] ****************************************************************************************************************************************
2020-09-08 21:14:43,080 p=88477 u=ganti n=ansible | META: ran handlers
2020-09-08 21:14:43,087 p=88477 u=ganti n=ansible | TASK [tcp : include_tasks] **************************************************************************************************************************************
2020-09-08 21:14:43,087 p=88477 u=ganti n=ansible | task path: /Users/ganti/Code/ansible-tower/roles/tcp/tasks/main.yml:1
2020-09-08 21:14:43,087 p=88477 u=ganti n=ansible | Tuesday 08 September 2020  21:14:43 -0400 (0:00:00.037)       0:00:00.037 ***** 
2020-09-08 21:14:43,269 p=88477 u=ganti n=ansible | included: /Users/ganti/Code/ansible-tower/roles/tcp/tasks/tcp.yml for localhost
2020-09-08 21:14:43,276 p=88477 u=ganti n=ansible | TASK [tcp : Deploy an tcp app service configuration] ************************************************************************************************************
2020-09-08 21:14:43,276 p=88477 u=ganti n=ansible | task path: /Users/ganti/Code/ansible-tower/roles/tcp/tasks/tcp.yml:1
2020-09-08 21:14:43,276 p=88477 u=ganti n=ansible | Tuesday 08 September 2020  21:14:43 -0400 (0:00:00.188)       0:00:00.226 ***** 
2020-09-08 21:14:43,309 p=88477 u=ganti n=ansible | fatal: [localhost]: FAILED! => {
    "msg": "The task includes an option with an undefined variable. The error was: 'password' is undefined\n\nThe error appears to be in '/Users/ganti/Code/ansible-tower/roles/tcp/tasks/tcp.yml': line 1, column 3, but may\nbe elsewhere in the file depending on the exact syntax problem.\n\nThe offending line appears to be:\n\n\n- name: Deploy an tcp app service configuration\n  ^ here\n"
}
2020-09-08 21:16:40,493 p=88477 u=ganti n=ansible | User interrupted execution
2020-09-08 21:16:42,264 p=88821 u=ganti n=ansible | ansible-playbook 2.9.5
  config file = /Users/ganti/Code/ansible-tower/ansible.cfg
  configured module search path = ['/Users/ganti/.ansible/plugins/modules', '/usr/share/ansible/plugins/modules']
  ansible python module location = /usr/local/lib/python3.7/site-packages/ansible
  executable location = /usr/local/bin/ansible-playbook
  python version = 3.7.4 (default, Sep  7 2019, 18:27:02) [Clang 10.0.1 (clang-1001.0.46.4)]
2020-09-08 21:16:42,265 p=88821 u=ganti n=ansible | Using /Users/ganti/Code/ansible-tower/ansible.cfg as config file
2020-09-08 21:16:42,275 p=88821 u=ganti n=ansible | host_list declined parsing /Users/ganti/Code/ansible-tower/inventory/dev/hosts as it did not pass its verify_file() method
2020-09-08 21:16:42,276 p=88821 u=ganti n=ansible | script declined parsing /Users/ganti/Code/ansible-tower/inventory/dev/hosts as it did not pass its verify_file() method
2020-09-08 21:16:42,276 p=88821 u=ganti n=ansible | auto declined parsing /Users/ganti/Code/ansible-tower/inventory/dev/hosts as it did not pass its verify_file() method
2020-09-08 21:16:42,280 p=88821 u=ganti n=ansible | [DEPRECATION WARNING]: The TRANSFORM_INVALID_GROUP_CHARS settings is set to allow bad characters in group names by default, this will change, but still be user 
configurable on deprecation. This feature will be removed in version 2.10. Deprecation warnings can be disabled by setting deprecation_warnings=False in 
ansible.cfg.
2020-09-08 21:16:42,281 p=88821 u=ganti n=ansible | [WARNING]: Invalid characters were found in group names but not replaced, use -vvvv to see details

2020-09-08 21:16:42,281 p=88821 u=ganti n=ansible | Parsed /Users/ganti/Code/ansible-tower/inventory/dev/hosts inventory source with ini plugin
2020-09-08 21:16:42,607 p=88821 u=ganti n=ansible | ERROR! the role 'ttcp' was not found in /Users/ganti/Code/ansible-tower/roles:/Users/ganti/Code/ansible-tower/roles:/Users/ganti/Code/ansible-tower

The error appears to be in '/Users/ganti/Code/ansible-tower/app.yml': line 11, column 7, but may
be elsewhere in the file depending on the exact syntax problem.

The offending line appears to be:

  roles:
    - "{{ role }}"
      ^ here
We could be wrong, but this one looks like it might be an issue with
missing quotes. Always quote template expression brackets when they
start a value. For instance:

    with_items:
      - {{ foo }}

Should be written as:

    with_items:
      - "{{ foo }}"

2020-09-08 21:16:46,842 p=88870 u=ganti n=ansible | ansible-playbook 2.9.5
  config file = /Users/ganti/Code/ansible-tower/ansible.cfg
  configured module search path = ['/Users/ganti/.ansible/plugins/modules', '/usr/share/ansible/plugins/modules']
  ansible python module location = /usr/local/lib/python3.7/site-packages/ansible
  executable location = /usr/local/bin/ansible-playbook
  python version = 3.7.4 (default, Sep  7 2019, 18:27:02) [Clang 10.0.1 (clang-1001.0.46.4)]
2020-09-08 21:16:46,842 p=88870 u=ganti n=ansible | Using /Users/ganti/Code/ansible-tower/ansible.cfg as config file
2020-09-08 21:16:46,848 p=88870 u=ganti n=ansible | host_list declined parsing /Users/ganti/Code/ansible-tower/inventory/dev/hosts as it did not pass its verify_file() method
2020-09-08 21:16:46,848 p=88870 u=ganti n=ansible | script declined parsing /Users/ganti/Code/ansible-tower/inventory/dev/hosts as it did not pass its verify_file() method
2020-09-08 21:16:46,849 p=88870 u=ganti n=ansible | auto declined parsing /Users/ganti/Code/ansible-tower/inventory/dev/hosts as it did not pass its verify_file() method
2020-09-08 21:16:46,851 p=88870 u=ganti n=ansible | [DEPRECATION WARNING]: The TRANSFORM_INVALID_GROUP_CHARS settings is set to allow bad characters in group names by default, this will change, but still be user 
configurable on deprecation. This feature will be removed in version 2.10. Deprecation warnings can be disabled by setting deprecation_warnings=False in 
ansible.cfg.
2020-09-08 21:16:46,852 p=88870 u=ganti n=ansible | [WARNING]: Invalid characters were found in group names but not replaced, use -vvvv to see details

2020-09-08 21:16:46,852 p=88870 u=ganti n=ansible | Parsed /Users/ganti/Code/ansible-tower/inventory/dev/hosts inventory source with ini plugin
2020-09-08 21:16:47,139 p=88870 u=ganti n=ansible | PLAYBOOK: app.yml ***********************************************************************************************************************************************
2020-09-08 21:16:47,140 p=88870 u=ganti n=ansible | 1 plays in app.yml
2020-09-08 21:16:47,141 p=88870 u=ganti n=ansible | PLAY [Big IP Operations] ****************************************************************************************************************************************
2020-09-08 21:16:47,151 p=88870 u=ganti n=ansible | META: ran handlers
2020-09-08 21:16:47,157 p=88870 u=ganti n=ansible | TASK [tcp : include_tasks] **************************************************************************************************************************************
2020-09-08 21:16:47,157 p=88870 u=ganti n=ansible | task path: /Users/ganti/Code/ansible-tower/roles/tcp/tasks/main.yml:1
2020-09-08 21:16:47,157 p=88870 u=ganti n=ansible | Tuesday 08 September 2020  21:16:47 -0400 (0:00:00.030)       0:00:00.030 ***** 
2020-09-08 21:16:47,234 p=88870 u=ganti n=ansible | included: /Users/ganti/Code/ansible-tower/roles/tcp/tasks/tcp.yml for localhost
2020-09-08 21:16:47,241 p=88870 u=ganti n=ansible | TASK [tcp : Deploy an tcp app service configuration] ************************************************************************************************************
2020-09-08 21:16:47,241 p=88870 u=ganti n=ansible | task path: /Users/ganti/Code/ansible-tower/roles/tcp/tasks/tcp.yml:1
2020-09-08 21:16:47,242 p=88870 u=ganti n=ansible | Tuesday 08 September 2020  21:16:47 -0400 (0:00:00.084)       0:00:00.114 ***** 
2020-09-08 21:16:47,274 p=88870 u=ganti n=ansible | fatal: [localhost]: FAILED! => {
    "msg": "The task includes an option with an undefined variable. The error was: 'password' is undefined\n\nThe error appears to be in '/Users/ganti/Code/ansible-tower/roles/tcp/tasks/tcp.yml': line 1, column 3, but may\nbe elsewhere in the file depending on the exact syntax problem.\n\nThe offending line appears to be:\n\n\n- name: Deploy an tcp app service configuration\n  ^ here\n"
}
2020-09-08 21:17:30,424 p=88870 u=ganti n=ansible | User interrupted execution
2020-09-08 21:34:53,840 p=97937 u=ganti n=ansible | ansible-playbook 2.9.5
  config file = /Users/ganti/Code/ansible-tower/ansible.cfg
  configured module search path = ['/Users/ganti/.ansible/plugins/modules', '/usr/share/ansible/plugins/modules']
  ansible python module location = /usr/local/lib/python3.7/site-packages/ansible
  executable location = /usr/local/bin/ansible-playbook
  python version = 3.7.4 (default, Sep  7 2019, 18:27:02) [Clang 10.0.1 (clang-1001.0.46.4)]
2020-09-08 21:34:53,841 p=97937 u=ganti n=ansible | Using /Users/ganti/Code/ansible-tower/ansible.cfg as config file
2020-09-08 21:34:53,851 p=97937 u=ganti n=ansible | host_list declined parsing /Users/ganti/Code/ansible-tower/inventory/dev/hosts as it did not pass its verify_file() method
2020-09-08 21:34:53,852 p=97937 u=ganti n=ansible | script declined parsing /Users/ganti/Code/ansible-tower/inventory/dev/hosts as it did not pass its verify_file() method
2020-09-08 21:34:53,852 p=97937 u=ganti n=ansible | auto declined parsing /Users/ganti/Code/ansible-tower/inventory/dev/hosts as it did not pass its verify_file() method
2020-09-08 21:34:53,856 p=97937 u=ganti n=ansible | [DEPRECATION WARNING]: The TRANSFORM_INVALID_GROUP_CHARS settings is set to allow bad characters in group names by default, this will change, but still be user 
configurable on deprecation. This feature will be removed in version 2.10. Deprecation warnings can be disabled by setting deprecation_warnings=False in 
ansible.cfg.
2020-09-08 21:34:53,856 p=97937 u=ganti n=ansible | [WARNING]: Invalid characters were found in group names but not replaced, use -vvvv to see details

2020-09-08 21:34:53,857 p=97937 u=ganti n=ansible | Parsed /Users/ganti/Code/ansible-tower/inventory/dev/hosts inventory source with ini plugin
2020-09-08 21:34:54,282 p=97937 u=ganti n=ansible | PLAYBOOK: app.yml ***********************************************************************************************************************************************
2020-09-08 21:34:54,282 p=97937 u=ganti n=ansible | 1 plays in app.yml
2020-09-08 21:34:54,283 p=97937 u=ganti n=ansible | PLAY [Big IP Operations] ****************************************************************************************************************************************
2020-09-08 21:34:54,294 p=97937 u=ganti n=ansible | META: ran handlers
2020-09-08 21:34:54,300 p=97937 u=ganti n=ansible | TASK [tcp : include_tasks] **************************************************************************************************************************************
2020-09-08 21:34:54,300 p=97937 u=ganti n=ansible | task path: /Users/ganti/Code/ansible-tower/roles/tcp/tasks/main.yml:1
2020-09-08 21:34:54,301 p=97937 u=ganti n=ansible | Tuesday 08 September 2020  21:34:54 -0400 (0:00:00.034)       0:00:00.034 ***** 
2020-09-08 21:34:54,445 p=97937 u=ganti n=ansible | included: /Users/ganti/Code/ansible-tower/roles/tcp/tasks/tcp.yml for localhost
2020-09-08 21:34:54,450 p=97937 u=ganti n=ansible | TASK [tcp : Deploy an tcp app service configuration] ************************************************************************************************************
2020-09-08 21:34:54,450 p=97937 u=ganti n=ansible | task path: /Users/ganti/Code/ansible-tower/roles/tcp/tasks/tcp.yml:1
2020-09-08 21:34:54,450 p=97937 u=ganti n=ansible | Tuesday 08 September 2020  21:34:54 -0400 (0:00:00.149)       0:00:00.184 ***** 
2020-09-08 21:34:54,693 p=97957 u=ganti n=ansible | Using module file /usr/local/lib/python3.7/site-packages/ansible/modules/network/f5/bigip_appsvcs_extension.py
2020-09-08 21:34:54,693 p=97957 u=ganti n=ansible | Pipelining is enabled.
2020-09-08 21:34:54,694 p=97957 u=ganti n=ansible | <localhost> ESTABLISH LOCAL CONNECTION FOR USER: ganti
2020-09-08 21:34:54,694 p=97957 u=ganti n=ansible | <localhost> EXEC /bin/sh -c '/usr/local/opt/python/bin/python3.7 && sleep 0'
2020-09-08 21:34:55,250 p=97937 u=ganti n=ansible | The full traceback is:
Traceback (most recent call last):
  File "/usr/local/Cellar/python/3.7.4_1/Frameworks/Python.framework/Versions/3.7/lib/python3.7/urllib/request.py", line 1317, in do_open
    encode_chunked=req.has_header('Transfer-encoding'))
  File "/usr/local/Cellar/python/3.7.4_1/Frameworks/Python.framework/Versions/3.7/lib/python3.7/http/client.py", line 1244, in request
    self._send_request(method, url, body, headers, encode_chunked)
  File "/usr/local/Cellar/python/3.7.4_1/Frameworks/Python.framework/Versions/3.7/lib/python3.7/http/client.py", line 1290, in _send_request
    self.endheaders(body, encode_chunked=encode_chunked)
  File "/usr/local/Cellar/python/3.7.4_1/Frameworks/Python.framework/Versions/3.7/lib/python3.7/http/client.py", line 1239, in endheaders
    self._send_output(message_body, encode_chunked=encode_chunked)
  File "/usr/local/Cellar/python/3.7.4_1/Frameworks/Python.framework/Versions/3.7/lib/python3.7/http/client.py", line 1026, in _send_output
    self.send(msg)
  File "/usr/local/Cellar/python/3.7.4_1/Frameworks/Python.framework/Versions/3.7/lib/python3.7/http/client.py", line 966, in send
    self.connect()
  File "/var/folders/94/gcvyc1g9191_npwtrl55hsq54jxlgs/T/ansible_bigip_appsvcs_extension_payload_95oa8aih/ansible_bigip_appsvcs_extension_payload.zip/ansible/module_utils/urls.py", line 430, in connect
  File "/usr/local/Cellar/python/3.7.4_1/Frameworks/Python.framework/Versions/3.7/lib/python3.7/ssl.py", line 423, in wrap_socket
    session=session
  File "/usr/local/Cellar/python/3.7.4_1/Frameworks/Python.framework/Versions/3.7/lib/python3.7/ssl.py", line 870, in _create
    self.do_handshake()
  File "/usr/local/Cellar/python/3.7.4_1/Frameworks/Python.framework/Versions/3.7/lib/python3.7/ssl.py", line 1139, in do_handshake
    self._sslobj.do_handshake()
ssl.SSLCertVerificationError: [SSL: CERTIFICATE_VERIFY_FAILED] certificate verify failed: self signed certificate (_ssl.c:1076)

During handling of the above exception, another exception occurred:

Traceback (most recent call last):
  File "<stdin>", line 102, in <module>
  File "<stdin>", line 94, in _ansiballz_main
  File "<stdin>", line 40, in invoke_module
  File "/usr/local/Cellar/python/3.7.4_1/Frameworks/Python.framework/Versions/3.7/lib/python3.7/runpy.py", line 205, in run_module
    return _run_module_code(code, init_globals, run_name, mod_spec)
  File "/usr/local/Cellar/python/3.7.4_1/Frameworks/Python.framework/Versions/3.7/lib/python3.7/runpy.py", line 96, in _run_module_code
    mod_name, mod_spec, pkg_name, script_name)
  File "/usr/local/Cellar/python/3.7.4_1/Frameworks/Python.framework/Versions/3.7/lib/python3.7/runpy.py", line 85, in _run_code
    exec(code, run_globals)
  File "/var/folders/94/gcvyc1g9191_npwtrl55hsq54jxlgs/T/ansible_bigip_appsvcs_extension_payload_95oa8aih/ansible_bigip_appsvcs_extension_payload.zip/ansible/modules/network/f5/bigip_appsvcs_extension.py", line 549, in <module>
  File "/var/folders/94/gcvyc1g9191_npwtrl55hsq54jxlgs/T/ansible_bigip_appsvcs_extension_payload_95oa8aih/ansible_bigip_appsvcs_extension_payload.zip/ansible/modules/network/f5/bigip_appsvcs_extension.py", line 542, in main
  File "/var/folders/94/gcvyc1g9191_npwtrl55hsq54jxlgs/T/ansible_bigip_appsvcs_extension_payload_95oa8aih/ansible_bigip_appsvcs_extension_payload.zip/ansible/modules/network/f5/bigip_appsvcs_extension.py", line 351, in exec_module
  File "/var/folders/94/gcvyc1g9191_npwtrl55hsq54jxlgs/T/ansible_bigip_appsvcs_extension_payload_95oa8aih/ansible_bigip_appsvcs_extension_payload.zip/ansible/modules/network/f5/bigip_appsvcs_extension.py", line 362, in present
  File "/var/folders/94/gcvyc1g9191_npwtrl55hsq54jxlgs/T/ansible_bigip_appsvcs_extension_payload_95oa8aih/ansible_bigip_appsvcs_extension_payload.zip/ansible/modules/network/f5/bigip_appsvcs_extension.py", line 461, in exists
  File "/var/folders/94/gcvyc1g9191_npwtrl55hsq54jxlgs/T/ansible_bigip_appsvcs_extension_payload_95oa8aih/ansible_bigip_appsvcs_extension_payload.zip/ansible/module_utils/network/f5/bigip.py", line 34, in api
  File "/var/folders/94/gcvyc1g9191_npwtrl55hsq54jxlgs/T/ansible_bigip_appsvcs_extension_payload_95oa8aih/ansible_bigip_appsvcs_extension_payload.zip/ansible/module_utils/network/f5/bigip.py", line 58, in connect_via_token_auth
  File "/var/folders/94/gcvyc1g9191_npwtrl55hsq54jxlgs/T/ansible_bigip_appsvcs_extension_payload_95oa8aih/ansible_bigip_appsvcs_extension_payload.zip/ansible/module_utils/network/f5/icontrol.py", line 238, in post
  File "/var/folders/94/gcvyc1g9191_npwtrl55hsq54jxlgs/T/ansible_bigip_appsvcs_extension_payload_95oa8aih/ansible_bigip_appsvcs_extension_payload.zip/ansible/module_utils/network/f5/icontrol.py", line 193, in send
  File "/var/folders/94/gcvyc1g9191_npwtrl55hsq54jxlgs/T/ansible_bigip_appsvcs_extension_payload_95oa8aih/ansible_bigip_appsvcs_extension_payload.zip/ansible/module_utils/urls.py", line 1294, in open
  File "/usr/local/Cellar/python/3.7.4_1/Frameworks/Python.framework/Versions/3.7/lib/python3.7/urllib/request.py", line 222, in urlopen
    return opener.open(url, data, timeout)
  File "/usr/local/Cellar/python/3.7.4_1/Frameworks/Python.framework/Versions/3.7/lib/python3.7/urllib/request.py", line 525, in open
    response = self._open(req, data)
  File "/usr/local/Cellar/python/3.7.4_1/Frameworks/Python.framework/Versions/3.7/lib/python3.7/urllib/request.py", line 543, in _open
    '_open', req)
  File "/usr/local/Cellar/python/3.7.4_1/Frameworks/Python.framework/Versions/3.7/lib/python3.7/urllib/request.py", line 503, in _call_chain
    result = func(*args)
  File "/var/folders/94/gcvyc1g9191_npwtrl55hsq54jxlgs/T/ansible_bigip_appsvcs_extension_payload_95oa8aih/ansible_bigip_appsvcs_extension_payload.zip/ansible/module_utils/urls.py", line 448, in https_open
  File "/usr/local/Cellar/python/3.7.4_1/Frameworks/Python.framework/Versions/3.7/lib/python3.7/urllib/request.py", line 1319, in do_open
    raise URLError(err)
urllib.error.URLError: <urlopen error [SSL: CERTIFICATE_VERIFY_FAILED] certificate verify failed: self signed certificate (_ssl.c:1076)>

2020-09-08 21:34:55,265 p=97937 u=ganti n=ansible | fatal: [localhost -> localhost]: FAILED! => {
    "changed": false,
    "module_stderr": "Traceback (most recent call last):\n  File \"/usr/local/Cellar/python/3.7.4_1/Frameworks/Python.framework/Versions/3.7/lib/python3.7/urllib/request.py\", line 1317, in do_open\n    encode_chunked=req.has_header('Transfer-encoding'))\n  File \"/usr/local/Cellar/python/3.7.4_1/Frameworks/Python.framework/Versions/3.7/lib/python3.7/http/client.py\", line 1244, in request\n    self._send_request(method, url, body, headers, encode_chunked)\n  File \"/usr/local/Cellar/python/3.7.4_1/Frameworks/Python.framework/Versions/3.7/lib/python3.7/http/client.py\", line 1290, in _send_request\n    self.endheaders(body, encode_chunked=encode_chunked)\n  File \"/usr/local/Cellar/python/3.7.4_1/Frameworks/Python.framework/Versions/3.7/lib/python3.7/http/client.py\", line 1239, in endheaders\n    self._send_output(message_body, encode_chunked=encode_chunked)\n  File \"/usr/local/Cellar/python/3.7.4_1/Frameworks/Python.framework/Versions/3.7/lib/python3.7/http/client.py\", line 1026, in _send_output\n    self.send(msg)\n  File \"/usr/local/Cellar/python/3.7.4_1/Frameworks/Python.framework/Versions/3.7/lib/python3.7/http/client.py\", line 966, in send\n    self.connect()\n  File \"/var/folders/94/gcvyc1g9191_npwtrl55hsq54jxlgs/T/ansible_bigip_appsvcs_extension_payload_95oa8aih/ansible_bigip_appsvcs_extension_payload.zip/ansible/module_utils/urls.py\", line 430, in connect\n  File \"/usr/local/Cellar/python/3.7.4_1/Frameworks/Python.framework/Versions/3.7/lib/python3.7/ssl.py\", line 423, in wrap_socket\n    session=session\n  File \"/usr/local/Cellar/python/3.7.4_1/Frameworks/Python.framework/Versions/3.7/lib/python3.7/ssl.py\", line 870, in _create\n    self.do_handshake()\n  File \"/usr/local/Cellar/python/3.7.4_1/Frameworks/Python.framework/Versions/3.7/lib/python3.7/ssl.py\", line 1139, in do_handshake\n    self._sslobj.do_handshake()\nssl.SSLCertVerificationError: [SSL: CERTIFICATE_VERIFY_FAILED] certificate verify failed: self signed certificate (_ssl.c:1076)\n\nDuring handling of the above exception, another exception occurred:\n\nTraceback (most recent call last):\n  File \"<stdin>\", line 102, in <module>\n  File \"<stdin>\", line 94, in _ansiballz_main\n  File \"<stdin>\", line 40, in invoke_module\n  File \"/usr/local/Cellar/python/3.7.4_1/Frameworks/Python.framework/Versions/3.7/lib/python3.7/runpy.py\", line 205, in run_module\n    return _run_module_code(code, init_globals, run_name, mod_spec)\n  File \"/usr/local/Cellar/python/3.7.4_1/Frameworks/Python.framework/Versions/3.7/lib/python3.7/runpy.py\", line 96, in _run_module_code\n    mod_name, mod_spec, pkg_name, script_name)\n  File \"/usr/local/Cellar/python/3.7.4_1/Frameworks/Python.framework/Versions/3.7/lib/python3.7/runpy.py\", line 85, in _run_code\n    exec(code, run_globals)\n  File \"/var/folders/94/gcvyc1g9191_npwtrl55hsq54jxlgs/T/ansible_bigip_appsvcs_extension_payload_95oa8aih/ansible_bigip_appsvcs_extension_payload.zip/ansible/modules/network/f5/bigip_appsvcs_extension.py\", line 549, in <module>\n  File \"/var/folders/94/gcvyc1g9191_npwtrl55hsq54jxlgs/T/ansible_bigip_appsvcs_extension_payload_95oa8aih/ansible_bigip_appsvcs_extension_payload.zip/ansible/modules/network/f5/bigip_appsvcs_extension.py\", line 542, in main\n  File \"/var/folders/94/gcvyc1g9191_npwtrl55hsq54jxlgs/T/ansible_bigip_appsvcs_extension_payload_95oa8aih/ansible_bigip_appsvcs_extension_payload.zip/ansible/modules/network/f5/bigip_appsvcs_extension.py\", line 351, in exec_module\n  File \"/var/folders/94/gcvyc1g9191_npwtrl55hsq54jxlgs/T/ansible_bigip_appsvcs_extension_payload_95oa8aih/ansible_bigip_appsvcs_extension_payload.zip/ansible/modules/network/f5/bigip_appsvcs_extension.py\", line 362, in present\n  File \"/var/folders/94/gcvyc1g9191_npwtrl55hsq54jxlgs/T/ansible_bigip_appsvcs_extension_payload_95oa8aih/ansible_bigip_appsvcs_extension_payload.zip/ansible/modules/network/f5/bigip_appsvcs_extension.py\", line 461, in exists\n  File \"/var/folders/94/gcvyc1g9191_npwtrl55hsq54jxlgs/T/ansible_bigip_appsvcs_extension_payload_95oa8aih/ansible_bigip_appsvcs_extension_payload.zip/ansible/module_utils/network/f5/bigip.py\", line 34, in api\n  File \"/var/folders/94/gcvyc1g9191_npwtrl55hsq54jxlgs/T/ansible_bigip_appsvcs_extension_payload_95oa8aih/ansible_bigip_appsvcs_extension_payload.zip/ansible/module_utils/network/f5/bigip.py\", line 58, in connect_via_token_auth\n  File \"/var/folders/94/gcvyc1g9191_npwtrl55hsq54jxlgs/T/ansible_bigip_appsvcs_extension_payload_95oa8aih/ansible_bigip_appsvcs_extension_payload.zip/ansible/module_utils/network/f5/icontrol.py\", line 238, in post\n  File \"/var/folders/94/gcvyc1g9191_npwtrl55hsq54jxlgs/T/ansible_bigip_appsvcs_extension_payload_95oa8aih/ansible_bigip_appsvcs_extension_payload.zip/ansible/module_utils/network/f5/icontrol.py\", line 193, in send\n  File \"/var/folders/94/gcvyc1g9191_npwtrl55hsq54jxlgs/T/ansible_bigip_appsvcs_extension_payload_95oa8aih/ansible_bigip_appsvcs_extension_payload.zip/ansible/module_utils/urls.py\", line 1294, in open\n  File \"/usr/local/Cellar/python/3.7.4_1/Frameworks/Python.framework/Versions/3.7/lib/python3.7/urllib/request.py\", line 222, in urlopen\n    return opener.open(url, data, timeout)\n  File \"/usr/local/Cellar/python/3.7.4_1/Frameworks/Python.framework/Versions/3.7/lib/python3.7/urllib/request.py\", line 525, in open\n    response = self._open(req, data)\n  File \"/usr/local/Cellar/python/3.7.4_1/Frameworks/Python.framework/Versions/3.7/lib/python3.7/urllib/request.py\", line 543, in _open\n    '_open', req)\n  File \"/usr/local/Cellar/python/3.7.4_1/Frameworks/Python.framework/Versions/3.7/lib/python3.7/urllib/request.py\", line 503, in _call_chain\n    result = func(*args)\n  File \"/var/folders/94/gcvyc1g9191_npwtrl55hsq54jxlgs/T/ansible_bigip_appsvcs_extension_payload_95oa8aih/ansible_bigip_appsvcs_extension_payload.zip/ansible/module_utils/urls.py\", line 448, in https_open\n  File \"/usr/local/Cellar/python/3.7.4_1/Frameworks/Python.framework/Versions/3.7/lib/python3.7/urllib/request.py\", line 1319, in do_open\n    raise URLError(err)\nurllib.error.URLError: <urlopen error [SSL: CERTIFICATE_VERIFY_FAILED] certificate verify failed: self signed certificate (_ssl.c:1076)>\n",
    "module_stdout": "",
    "msg": "MODULE FAILURE\nSee stdout/stderr for the exact error",
    "rc": 1
}
2020-09-08 21:35:10,846 p=97937 u=ganti n=ansible | User interrupted execution
2020-09-08 21:35:30,054 p=98075 u=ganti n=ansible | ansible-playbook 2.9.5
  config file = /Users/ganti/Code/ansible-tower/ansible.cfg
  configured module search path = ['/Users/ganti/.ansible/plugins/modules', '/usr/share/ansible/plugins/modules']
  ansible python module location = /usr/local/lib/python3.7/site-packages/ansible
  executable location = /usr/local/bin/ansible-playbook
  python version = 3.7.4 (default, Sep  7 2019, 18:27:02) [Clang 10.0.1 (clang-1001.0.46.4)]
2020-09-08 21:35:30,054 p=98075 u=ganti n=ansible | Using /Users/ganti/Code/ansible-tower/ansible.cfg as config file
2020-09-08 21:35:30,063 p=98075 u=ganti n=ansible | host_list declined parsing /Users/ganti/Code/ansible-tower/inventory/dev/hosts as it did not pass its verify_file() method
2020-09-08 21:35:30,064 p=98075 u=ganti n=ansible | script declined parsing /Users/ganti/Code/ansible-tower/inventory/dev/hosts as it did not pass its verify_file() method
2020-09-08 21:35:30,064 p=98075 u=ganti n=ansible | auto declined parsing /Users/ganti/Code/ansible-tower/inventory/dev/hosts as it did not pass its verify_file() method
2020-09-08 21:35:30,068 p=98075 u=ganti n=ansible | [DEPRECATION WARNING]: The TRANSFORM_INVALID_GROUP_CHARS settings is set to allow bad characters in group names by default, this will change, but still be user 
configurable on deprecation. This feature will be removed in version 2.10. Deprecation warnings can be disabled by setting deprecation_warnings=False in 
ansible.cfg.
2020-09-08 21:35:30,068 p=98075 u=ganti n=ansible | [WARNING]: Invalid characters were found in group names but not replaced, use -vvvv to see details

2020-09-08 21:35:30,069 p=98075 u=ganti n=ansible | Parsed /Users/ganti/Code/ansible-tower/inventory/dev/hosts inventory source with ini plugin
2020-09-08 21:35:30,470 p=98075 u=ganti n=ansible | PLAYBOOK: app.yml ***********************************************************************************************************************************************
2020-09-08 21:35:30,470 p=98075 u=ganti n=ansible | 1 plays in app.yml
2020-09-08 21:35:30,471 p=98075 u=ganti n=ansible | PLAY [Big IP Operations] ****************************************************************************************************************************************
2020-09-08 21:35:30,481 p=98075 u=ganti n=ansible | META: ran handlers
2020-09-08 21:35:30,487 p=98075 u=ganti n=ansible | TASK [tcp : include_tasks] **************************************************************************************************************************************
2020-09-08 21:35:30,487 p=98075 u=ganti n=ansible | task path: /Users/ganti/Code/ansible-tower/roles/tcp/tasks/main.yml:1
2020-09-08 21:35:30,487 p=98075 u=ganti n=ansible | Tuesday 08 September 2020  21:35:30 -0400 (0:00:00.029)       0:00:00.029 ***** 
2020-09-08 21:35:30,552 p=98075 u=ganti n=ansible | included: /Users/ganti/Code/ansible-tower/roles/tcp/tasks/tcp.yml for localhost
2020-09-08 21:35:30,557 p=98075 u=ganti n=ansible | TASK [tcp : Deploy an tcp app service configuration] ************************************************************************************************************
2020-09-08 21:35:30,558 p=98075 u=ganti n=ansible | task path: /Users/ganti/Code/ansible-tower/roles/tcp/tasks/tcp.yml:1
2020-09-08 21:35:30,558 p=98075 u=ganti n=ansible | Tuesday 08 September 2020  21:35:30 -0400 (0:00:00.070)       0:00:00.100 ***** 
2020-09-08 21:35:30,794 p=98080 u=ganti n=ansible | Using module file /usr/local/lib/python3.7/site-packages/ansible/modules/network/f5/bigip_appsvcs_extension.py
2020-09-08 21:35:30,795 p=98080 u=ganti n=ansible | Pipelining is enabled.
2020-09-08 21:35:30,795 p=98080 u=ganti n=ansible | <localhost> ESTABLISH LOCAL CONNECTION FOR USER: ganti
2020-09-08 21:35:30,796 p=98080 u=ganti n=ansible | <localhost> EXEC /bin/sh -c '/usr/local/opt/python/bin/python3.7 && sleep 0'
2020-09-08 21:35:31,264 p=98075 u=ganti n=ansible | The full traceback is:
Traceback (most recent call last):
  File "/usr/local/Cellar/python/3.7.4_1/Frameworks/Python.framework/Versions/3.7/lib/python3.7/urllib/request.py", line 1317, in do_open
    encode_chunked=req.has_header('Transfer-encoding'))
  File "/usr/local/Cellar/python/3.7.4_1/Frameworks/Python.framework/Versions/3.7/lib/python3.7/http/client.py", line 1244, in request
    self._send_request(method, url, body, headers, encode_chunked)
  File "/usr/local/Cellar/python/3.7.4_1/Frameworks/Python.framework/Versions/3.7/lib/python3.7/http/client.py", line 1290, in _send_request
    self.endheaders(body, encode_chunked=encode_chunked)
  File "/usr/local/Cellar/python/3.7.4_1/Frameworks/Python.framework/Versions/3.7/lib/python3.7/http/client.py", line 1239, in endheaders
    self._send_output(message_body, encode_chunked=encode_chunked)
  File "/usr/local/Cellar/python/3.7.4_1/Frameworks/Python.framework/Versions/3.7/lib/python3.7/http/client.py", line 1026, in _send_output
    self.send(msg)
  File "/usr/local/Cellar/python/3.7.4_1/Frameworks/Python.framework/Versions/3.7/lib/python3.7/http/client.py", line 966, in send
    self.connect()
  File "/var/folders/94/gcvyc1g9191_npwtrl55hsq54jxlgs/T/ansible_bigip_appsvcs_extension_payload_ncxl2uyo/ansible_bigip_appsvcs_extension_payload.zip/ansible/module_utils/urls.py", line 430, in connect
  File "/usr/local/Cellar/python/3.7.4_1/Frameworks/Python.framework/Versions/3.7/lib/python3.7/ssl.py", line 423, in wrap_socket
    session=session
  File "/usr/local/Cellar/python/3.7.4_1/Frameworks/Python.framework/Versions/3.7/lib/python3.7/ssl.py", line 870, in _create
    self.do_handshake()
  File "/usr/local/Cellar/python/3.7.4_1/Frameworks/Python.framework/Versions/3.7/lib/python3.7/ssl.py", line 1139, in do_handshake
    self._sslobj.do_handshake()
ssl.SSLCertVerificationError: [SSL: CERTIFICATE_VERIFY_FAILED] certificate verify failed: self signed certificate (_ssl.c:1076)

During handling of the above exception, another exception occurred:

Traceback (most recent call last):
  File "<stdin>", line 102, in <module>
  File "<stdin>", line 94, in _ansiballz_main
  File "<stdin>", line 40, in invoke_module
  File "/usr/local/Cellar/python/3.7.4_1/Frameworks/Python.framework/Versions/3.7/lib/python3.7/runpy.py", line 205, in run_module
    return _run_module_code(code, init_globals, run_name, mod_spec)
  File "/usr/local/Cellar/python/3.7.4_1/Frameworks/Python.framework/Versions/3.7/lib/python3.7/runpy.py", line 96, in _run_module_code
    mod_name, mod_spec, pkg_name, script_name)
  File "/usr/local/Cellar/python/3.7.4_1/Frameworks/Python.framework/Versions/3.7/lib/python3.7/runpy.py", line 85, in _run_code
    exec(code, run_globals)
  File "/var/folders/94/gcvyc1g9191_npwtrl55hsq54jxlgs/T/ansible_bigip_appsvcs_extension_payload_ncxl2uyo/ansible_bigip_appsvcs_extension_payload.zip/ansible/modules/network/f5/bigip_appsvcs_extension.py", line 549, in <module>
  File "/var/folders/94/gcvyc1g9191_npwtrl55hsq54jxlgs/T/ansible_bigip_appsvcs_extension_payload_ncxl2uyo/ansible_bigip_appsvcs_extension_payload.zip/ansible/modules/network/f5/bigip_appsvcs_extension.py", line 542, in main
  File "/var/folders/94/gcvyc1g9191_npwtrl55hsq54jxlgs/T/ansible_bigip_appsvcs_extension_payload_ncxl2uyo/ansible_bigip_appsvcs_extension_payload.zip/ansible/modules/network/f5/bigip_appsvcs_extension.py", line 351, in exec_module
  File "/var/folders/94/gcvyc1g9191_npwtrl55hsq54jxlgs/T/ansible_bigip_appsvcs_extension_payload_ncxl2uyo/ansible_bigip_appsvcs_extension_payload.zip/ansible/modules/network/f5/bigip_appsvcs_extension.py", line 362, in present
  File "/var/folders/94/gcvyc1g9191_npwtrl55hsq54jxlgs/T/ansible_bigip_appsvcs_extension_payload_ncxl2uyo/ansible_bigip_appsvcs_extension_payload.zip/ansible/modules/network/f5/bigip_appsvcs_extension.py", line 461, in exists
  File "/var/folders/94/gcvyc1g9191_npwtrl55hsq54jxlgs/T/ansible_bigip_appsvcs_extension_payload_ncxl2uyo/ansible_bigip_appsvcs_extension_payload.zip/ansible/module_utils/network/f5/bigip.py", line 34, in api
  File "/var/folders/94/gcvyc1g9191_npwtrl55hsq54jxlgs/T/ansible_bigip_appsvcs_extension_payload_ncxl2uyo/ansible_bigip_appsvcs_extension_payload.zip/ansible/module_utils/network/f5/bigip.py", line 58, in connect_via_token_auth
  File "/var/folders/94/gcvyc1g9191_npwtrl55hsq54jxlgs/T/ansible_bigip_appsvcs_extension_payload_ncxl2uyo/ansible_bigip_appsvcs_extension_payload.zip/ansible/module_utils/network/f5/icontrol.py", line 238, in post
  File "/var/folders/94/gcvyc1g9191_npwtrl55hsq54jxlgs/T/ansible_bigip_appsvcs_extension_payload_ncxl2uyo/ansible_bigip_appsvcs_extension_payload.zip/ansible/module_utils/network/f5/icontrol.py", line 193, in send
  File "/var/folders/94/gcvyc1g9191_npwtrl55hsq54jxlgs/T/ansible_bigip_appsvcs_extension_payload_ncxl2uyo/ansible_bigip_appsvcs_extension_payload.zip/ansible/module_utils/urls.py", line 1294, in open
  File "/usr/local/Cellar/python/3.7.4_1/Frameworks/Python.framework/Versions/3.7/lib/python3.7/urllib/request.py", line 222, in urlopen
    return opener.open(url, data, timeout)
  File "/usr/local/Cellar/python/3.7.4_1/Frameworks/Python.framework/Versions/3.7/lib/python3.7/urllib/request.py", line 525, in open
    response = self._open(req, data)
  File "/usr/local/Cellar/python/3.7.4_1/Frameworks/Python.framework/Versions/3.7/lib/python3.7/urllib/request.py", line 543, in _open
    '_open', req)
  File "/usr/local/Cellar/python/3.7.4_1/Frameworks/Python.framework/Versions/3.7/lib/python3.7/urllib/request.py", line 503, in _call_chain
    result = func(*args)
  File "/var/folders/94/gcvyc1g9191_npwtrl55hsq54jxlgs/T/ansible_bigip_appsvcs_extension_payload_ncxl2uyo/ansible_bigip_appsvcs_extension_payload.zip/ansible/module_utils/urls.py", line 448, in https_open
  File "/usr/local/Cellar/python/3.7.4_1/Frameworks/Python.framework/Versions/3.7/lib/python3.7/urllib/request.py", line 1319, in do_open
    raise URLError(err)
urllib.error.URLError: <urlopen error [SSL: CERTIFICATE_VERIFY_FAILED] certificate verify failed: self signed certificate (_ssl.c:1076)>

2020-09-08 21:35:31,283 p=98075 u=ganti n=ansible | fatal: [localhost -> localhost]: FAILED! => {
    "changed": false,
    "module_stderr": "Traceback (most recent call last):\n  File \"/usr/local/Cellar/python/3.7.4_1/Frameworks/Python.framework/Versions/3.7/lib/python3.7/urllib/request.py\", line 1317, in do_open\n    encode_chunked=req.has_header('Transfer-encoding'))\n  File \"/usr/local/Cellar/python/3.7.4_1/Frameworks/Python.framework/Versions/3.7/lib/python3.7/http/client.py\", line 1244, in request\n    self._send_request(method, url, body, headers, encode_chunked)\n  File \"/usr/local/Cellar/python/3.7.4_1/Frameworks/Python.framework/Versions/3.7/lib/python3.7/http/client.py\", line 1290, in _send_request\n    self.endheaders(body, encode_chunked=encode_chunked)\n  File \"/usr/local/Cellar/python/3.7.4_1/Frameworks/Python.framework/Versions/3.7/lib/python3.7/http/client.py\", line 1239, in endheaders\n    self._send_output(message_body, encode_chunked=encode_chunked)\n  File \"/usr/local/Cellar/python/3.7.4_1/Frameworks/Python.framework/Versions/3.7/lib/python3.7/http/client.py\", line 1026, in _send_output\n    self.send(msg)\n  File \"/usr/local/Cellar/python/3.7.4_1/Frameworks/Python.framework/Versions/3.7/lib/python3.7/http/client.py\", line 966, in send\n    self.connect()\n  File \"/var/folders/94/gcvyc1g9191_npwtrl55hsq54jxlgs/T/ansible_bigip_appsvcs_extension_payload_ncxl2uyo/ansible_bigip_appsvcs_extension_payload.zip/ansible/module_utils/urls.py\", line 430, in connect\n  File \"/usr/local/Cellar/python/3.7.4_1/Frameworks/Python.framework/Versions/3.7/lib/python3.7/ssl.py\", line 423, in wrap_socket\n    session=session\n  File \"/usr/local/Cellar/python/3.7.4_1/Frameworks/Python.framework/Versions/3.7/lib/python3.7/ssl.py\", line 870, in _create\n    self.do_handshake()\n  File \"/usr/local/Cellar/python/3.7.4_1/Frameworks/Python.framework/Versions/3.7/lib/python3.7/ssl.py\", line 1139, in do_handshake\n    self._sslobj.do_handshake()\nssl.SSLCertVerificationError: [SSL: CERTIFICATE_VERIFY_FAILED] certificate verify failed: self signed certificate (_ssl.c:1076)\n\nDuring handling of the above exception, another exception occurred:\n\nTraceback (most recent call last):\n  File \"<stdin>\", line 102, in <module>\n  File \"<stdin>\", line 94, in _ansiballz_main\n  File \"<stdin>\", line 40, in invoke_module\n  File \"/usr/local/Cellar/python/3.7.4_1/Frameworks/Python.framework/Versions/3.7/lib/python3.7/runpy.py\", line 205, in run_module\n    return _run_module_code(code, init_globals, run_name, mod_spec)\n  File \"/usr/local/Cellar/python/3.7.4_1/Frameworks/Python.framework/Versions/3.7/lib/python3.7/runpy.py\", line 96, in _run_module_code\n    mod_name, mod_spec, pkg_name, script_name)\n  File \"/usr/local/Cellar/python/3.7.4_1/Frameworks/Python.framework/Versions/3.7/lib/python3.7/runpy.py\", line 85, in _run_code\n    exec(code, run_globals)\n  File \"/var/folders/94/gcvyc1g9191_npwtrl55hsq54jxlgs/T/ansible_bigip_appsvcs_extension_payload_ncxl2uyo/ansible_bigip_appsvcs_extension_payload.zip/ansible/modules/network/f5/bigip_appsvcs_extension.py\", line 549, in <module>\n  File \"/var/folders/94/gcvyc1g9191_npwtrl55hsq54jxlgs/T/ansible_bigip_appsvcs_extension_payload_ncxl2uyo/ansible_bigip_appsvcs_extension_payload.zip/ansible/modules/network/f5/bigip_appsvcs_extension.py\", line 542, in main\n  File \"/var/folders/94/gcvyc1g9191_npwtrl55hsq54jxlgs/T/ansible_bigip_appsvcs_extension_payload_ncxl2uyo/ansible_bigip_appsvcs_extension_payload.zip/ansible/modules/network/f5/bigip_appsvcs_extension.py\", line 351, in exec_module\n  File \"/var/folders/94/gcvyc1g9191_npwtrl55hsq54jxlgs/T/ansible_bigip_appsvcs_extension_payload_ncxl2uyo/ansible_bigip_appsvcs_extension_payload.zip/ansible/modules/network/f5/bigip_appsvcs_extension.py\", line 362, in present\n  File \"/var/folders/94/gcvyc1g9191_npwtrl55hsq54jxlgs/T/ansible_bigip_appsvcs_extension_payload_ncxl2uyo/ansible_bigip_appsvcs_extension_payload.zip/ansible/modules/network/f5/bigip_appsvcs_extension.py\", line 461, in exists\n  File \"/var/folders/94/gcvyc1g9191_npwtrl55hsq54jxlgs/T/ansible_bigip_appsvcs_extension_payload_ncxl2uyo/ansible_bigip_appsvcs_extension_payload.zip/ansible/module_utils/network/f5/bigip.py\", line 34, in api\n  File \"/var/folders/94/gcvyc1g9191_npwtrl55hsq54jxlgs/T/ansible_bigip_appsvcs_extension_payload_ncxl2uyo/ansible_bigip_appsvcs_extension_payload.zip/ansible/module_utils/network/f5/bigip.py\", line 58, in connect_via_token_auth\n  File \"/var/folders/94/gcvyc1g9191_npwtrl55hsq54jxlgs/T/ansible_bigip_appsvcs_extension_payload_ncxl2uyo/ansible_bigip_appsvcs_extension_payload.zip/ansible/module_utils/network/f5/icontrol.py\", line 238, in post\n  File \"/var/folders/94/gcvyc1g9191_npwtrl55hsq54jxlgs/T/ansible_bigip_appsvcs_extension_payload_ncxl2uyo/ansible_bigip_appsvcs_extension_payload.zip/ansible/module_utils/network/f5/icontrol.py\", line 193, in send\n  File \"/var/folders/94/gcvyc1g9191_npwtrl55hsq54jxlgs/T/ansible_bigip_appsvcs_extension_payload_ncxl2uyo/ansible_bigip_appsvcs_extension_payload.zip/ansible/module_utils/urls.py\", line 1294, in open\n  File \"/usr/local/Cellar/python/3.7.4_1/Frameworks/Python.framework/Versions/3.7/lib/python3.7/urllib/request.py\", line 222, in urlopen\n    return opener.open(url, data, timeout)\n  File \"/usr/local/Cellar/python/3.7.4_1/Frameworks/Python.framework/Versions/3.7/lib/python3.7/urllib/request.py\", line 525, in open\n    response = self._open(req, data)\n  File \"/usr/local/Cellar/python/3.7.4_1/Frameworks/Python.framework/Versions/3.7/lib/python3.7/urllib/request.py\", line 543, in _open\n    '_open', req)\n  File \"/usr/local/Cellar/python/3.7.4_1/Frameworks/Python.framework/Versions/3.7/lib/python3.7/urllib/request.py\", line 503, in _call_chain\n    result = func(*args)\n  File \"/var/folders/94/gcvyc1g9191_npwtrl55hsq54jxlgs/T/ansible_bigip_appsvcs_extension_payload_ncxl2uyo/ansible_bigip_appsvcs_extension_payload.zip/ansible/module_utils/urls.py\", line 448, in https_open\n  File \"/usr/local/Cellar/python/3.7.4_1/Frameworks/Python.framework/Versions/3.7/lib/python3.7/urllib/request.py\", line 1319, in do_open\n    raise URLError(err)\nurllib.error.URLError: <urlopen error [SSL: CERTIFICATE_VERIFY_FAILED] certificate verify failed: self signed certificate (_ssl.c:1076)>\n",
    "module_stdout": "",
    "msg": "MODULE FAILURE\nSee stdout/stderr for the exact error",
    "rc": 1
}
2020-09-08 21:35:43,647 p=98075 u=ganti n=ansible | User interrupted execution
2020-09-08 21:35:59,542 p=98176 u=ganti n=ansible | ansible-playbook 2.9.5
  config file = /Users/ganti/Code/ansible-tower/ansible.cfg
  configured module search path = ['/Users/ganti/.ansible/plugins/modules', '/usr/share/ansible/plugins/modules']
  ansible python module location = /usr/local/lib/python3.7/site-packages/ansible
  executable location = /usr/local/bin/ansible-playbook
  python version = 3.7.4 (default, Sep  7 2019, 18:27:02) [Clang 10.0.1 (clang-1001.0.46.4)]
2020-09-08 21:35:59,542 p=98176 u=ganti n=ansible | Using /Users/ganti/Code/ansible-tower/ansible.cfg as config file
2020-09-08 21:35:59,549 p=98176 u=ganti n=ansible | host_list declined parsing /Users/ganti/Code/ansible-tower/inventory/dev/hosts as it did not pass its verify_file() method
2020-09-08 21:35:59,549 p=98176 u=ganti n=ansible | script declined parsing /Users/ganti/Code/ansible-tower/inventory/dev/hosts as it did not pass its verify_file() method
2020-09-08 21:35:59,549 p=98176 u=ganti n=ansible | auto declined parsing /Users/ganti/Code/ansible-tower/inventory/dev/hosts as it did not pass its verify_file() method
2020-09-08 21:35:59,552 p=98176 u=ganti n=ansible | [DEPRECATION WARNING]: The TRANSFORM_INVALID_GROUP_CHARS settings is set to allow bad characters in group names by default, this will change, but still be user 
configurable on deprecation. This feature will be removed in version 2.10. Deprecation warnings can be disabled by setting deprecation_warnings=False in 
ansible.cfg.
2020-09-08 21:35:59,552 p=98176 u=ganti n=ansible | [WARNING]: Invalid characters were found in group names but not replaced, use -vvvv to see details

2020-09-08 21:35:59,557 p=98176 u=ganti n=ansible | Parsed /Users/ganti/Code/ansible-tower/inventory/dev/hosts inventory source with ini plugin
2020-09-08 21:35:59,838 p=98176 u=ganti n=ansible | PLAYBOOK: app.yml ***********************************************************************************************************************************************
2020-09-08 21:35:59,839 p=98176 u=ganti n=ansible | 1 plays in app.yml
2020-09-08 21:35:59,840 p=98176 u=ganti n=ansible | PLAY [Big IP Operations] ****************************************************************************************************************************************
2020-09-08 21:35:59,847 p=98176 u=ganti n=ansible | META: ran handlers
2020-09-08 21:35:59,852 p=98176 u=ganti n=ansible | TASK [tcp : include_tasks] **************************************************************************************************************************************
2020-09-08 21:35:59,852 p=98176 u=ganti n=ansible | task path: /Users/ganti/Code/ansible-tower/roles/tcp/tasks/main.yml:1
2020-09-08 21:35:59,852 p=98176 u=ganti n=ansible | Tuesday 08 September 2020  21:35:59 -0400 (0:00:00.024)       0:00:00.024 ***** 
2020-09-08 21:35:59,915 p=98176 u=ganti n=ansible | included: /Users/ganti/Code/ansible-tower/roles/tcp/tasks/tcp.yml for localhost
2020-09-08 21:35:59,920 p=98176 u=ganti n=ansible | TASK [tcp : Deploy an tcp app service configuration] ************************************************************************************************************
2020-09-08 21:35:59,920 p=98176 u=ganti n=ansible | task path: /Users/ganti/Code/ansible-tower/roles/tcp/tasks/tcp.yml:1
2020-09-08 21:35:59,920 p=98176 u=ganti n=ansible | Tuesday 08 September 2020  21:35:59 -0400 (0:00:00.067)       0:00:00.092 ***** 
2020-09-08 21:36:00,138 p=98181 u=ganti n=ansible | Using module file /usr/local/lib/python3.7/site-packages/ansible/modules/network/f5/bigip_appsvcs_extension.py
2020-09-08 21:36:00,138 p=98181 u=ganti n=ansible | Pipelining is enabled.
2020-09-08 21:36:00,138 p=98181 u=ganti n=ansible | <localhost> ESTABLISH LOCAL CONNECTION FOR USER: ganti
2020-09-08 21:36:00,139 p=98181 u=ganti n=ansible | <localhost> EXEC /bin/sh -c '/usr/local/opt/python/bin/python3.7 && sleep 0'
2020-09-08 21:36:00,592 p=98176 u=ganti n=ansible | The full traceback is:
Traceback (most recent call last):
  File "/usr/local/Cellar/python/3.7.4_1/Frameworks/Python.framework/Versions/3.7/lib/python3.7/urllib/request.py", line 1317, in do_open
    encode_chunked=req.has_header('Transfer-encoding'))
  File "/usr/local/Cellar/python/3.7.4_1/Frameworks/Python.framework/Versions/3.7/lib/python3.7/http/client.py", line 1244, in request
    self._send_request(method, url, body, headers, encode_chunked)
  File "/usr/local/Cellar/python/3.7.4_1/Frameworks/Python.framework/Versions/3.7/lib/python3.7/http/client.py", line 1290, in _send_request
    self.endheaders(body, encode_chunked=encode_chunked)
  File "/usr/local/Cellar/python/3.7.4_1/Frameworks/Python.framework/Versions/3.7/lib/python3.7/http/client.py", line 1239, in endheaders
    self._send_output(message_body, encode_chunked=encode_chunked)
  File "/usr/local/Cellar/python/3.7.4_1/Frameworks/Python.framework/Versions/3.7/lib/python3.7/http/client.py", line 1026, in _send_output
    self.send(msg)
  File "/usr/local/Cellar/python/3.7.4_1/Frameworks/Python.framework/Versions/3.7/lib/python3.7/http/client.py", line 966, in send
    self.connect()
  File "/var/folders/94/gcvyc1g9191_npwtrl55hsq54jxlgs/T/ansible_bigip_appsvcs_extension_payload_dxv7a4vm/ansible_bigip_appsvcs_extension_payload.zip/ansible/module_utils/urls.py", line 430, in connect
  File "/usr/local/Cellar/python/3.7.4_1/Frameworks/Python.framework/Versions/3.7/lib/python3.7/ssl.py", line 423, in wrap_socket
    session=session
  File "/usr/local/Cellar/python/3.7.4_1/Frameworks/Python.framework/Versions/3.7/lib/python3.7/ssl.py", line 870, in _create
    self.do_handshake()
  File "/usr/local/Cellar/python/3.7.4_1/Frameworks/Python.framework/Versions/3.7/lib/python3.7/ssl.py", line 1139, in do_handshake
    self._sslobj.do_handshake()
ssl.SSLCertVerificationError: [SSL: CERTIFICATE_VERIFY_FAILED] certificate verify failed: self signed certificate (_ssl.c:1076)

During handling of the above exception, another exception occurred:

Traceback (most recent call last):
  File "<stdin>", line 102, in <module>
  File "<stdin>", line 94, in _ansiballz_main
  File "<stdin>", line 40, in invoke_module
  File "/usr/local/Cellar/python/3.7.4_1/Frameworks/Python.framework/Versions/3.7/lib/python3.7/runpy.py", line 205, in run_module
    return _run_module_code(code, init_globals, run_name, mod_spec)
  File "/usr/local/Cellar/python/3.7.4_1/Frameworks/Python.framework/Versions/3.7/lib/python3.7/runpy.py", line 96, in _run_module_code
    mod_name, mod_spec, pkg_name, script_name)
  File "/usr/local/Cellar/python/3.7.4_1/Frameworks/Python.framework/Versions/3.7/lib/python3.7/runpy.py", line 85, in _run_code
    exec(code, run_globals)
  File "/var/folders/94/gcvyc1g9191_npwtrl55hsq54jxlgs/T/ansible_bigip_appsvcs_extension_payload_dxv7a4vm/ansible_bigip_appsvcs_extension_payload.zip/ansible/modules/network/f5/bigip_appsvcs_extension.py", line 549, in <module>
  File "/var/folders/94/gcvyc1g9191_npwtrl55hsq54jxlgs/T/ansible_bigip_appsvcs_extension_payload_dxv7a4vm/ansible_bigip_appsvcs_extension_payload.zip/ansible/modules/network/f5/bigip_appsvcs_extension.py", line 542, in main
  File "/var/folders/94/gcvyc1g9191_npwtrl55hsq54jxlgs/T/ansible_bigip_appsvcs_extension_payload_dxv7a4vm/ansible_bigip_appsvcs_extension_payload.zip/ansible/modules/network/f5/bigip_appsvcs_extension.py", line 351, in exec_module
  File "/var/folders/94/gcvyc1g9191_npwtrl55hsq54jxlgs/T/ansible_bigip_appsvcs_extension_payload_dxv7a4vm/ansible_bigip_appsvcs_extension_payload.zip/ansible/modules/network/f5/bigip_appsvcs_extension.py", line 362, in present
  File "/var/folders/94/gcvyc1g9191_npwtrl55hsq54jxlgs/T/ansible_bigip_appsvcs_extension_payload_dxv7a4vm/ansible_bigip_appsvcs_extension_payload.zip/ansible/modules/network/f5/bigip_appsvcs_extension.py", line 461, in exists
  File "/var/folders/94/gcvyc1g9191_npwtrl55hsq54jxlgs/T/ansible_bigip_appsvcs_extension_payload_dxv7a4vm/ansible_bigip_appsvcs_extension_payload.zip/ansible/module_utils/network/f5/bigip.py", line 34, in api
  File "/var/folders/94/gcvyc1g9191_npwtrl55hsq54jxlgs/T/ansible_bigip_appsvcs_extension_payload_dxv7a4vm/ansible_bigip_appsvcs_extension_payload.zip/ansible/module_utils/network/f5/bigip.py", line 58, in connect_via_token_auth
  File "/var/folders/94/gcvyc1g9191_npwtrl55hsq54jxlgs/T/ansible_bigip_appsvcs_extension_payload_dxv7a4vm/ansible_bigip_appsvcs_extension_payload.zip/ansible/module_utils/network/f5/icontrol.py", line 238, in post
  File "/var/folders/94/gcvyc1g9191_npwtrl55hsq54jxlgs/T/ansible_bigip_appsvcs_extension_payload_dxv7a4vm/ansible_bigip_appsvcs_extension_payload.zip/ansible/module_utils/network/f5/icontrol.py", line 193, in send
  File "/var/folders/94/gcvyc1g9191_npwtrl55hsq54jxlgs/T/ansible_bigip_appsvcs_extension_payload_dxv7a4vm/ansible_bigip_appsvcs_extension_payload.zip/ansible/module_utils/urls.py", line 1294, in open
  File "/usr/local/Cellar/python/3.7.4_1/Frameworks/Python.framework/Versions/3.7/lib/python3.7/urllib/request.py", line 222, in urlopen
    return opener.open(url, data, timeout)
  File "/usr/local/Cellar/python/3.7.4_1/Frameworks/Python.framework/Versions/3.7/lib/python3.7/urllib/request.py", line 525, in open
    response = self._open(req, data)
  File "/usr/local/Cellar/python/3.7.4_1/Frameworks/Python.framework/Versions/3.7/lib/python3.7/urllib/request.py", line 543, in _open
    '_open', req)
  File "/usr/local/Cellar/python/3.7.4_1/Frameworks/Python.framework/Versions/3.7/lib/python3.7/urllib/request.py", line 503, in _call_chain
    result = func(*args)
  File "/var/folders/94/gcvyc1g9191_npwtrl55hsq54jxlgs/T/ansible_bigip_appsvcs_extension_payload_dxv7a4vm/ansible_bigip_appsvcs_extension_payload.zip/ansible/module_utils/urls.py", line 448, in https_open
  File "/usr/local/Cellar/python/3.7.4_1/Frameworks/Python.framework/Versions/3.7/lib/python3.7/urllib/request.py", line 1319, in do_open
    raise URLError(err)
urllib.error.URLError: <urlopen error [SSL: CERTIFICATE_VERIFY_FAILED] certificate verify failed: self signed certificate (_ssl.c:1076)>

2020-09-08 21:36:00,609 p=98176 u=ganti n=ansible | fatal: [localhost -> localhost]: FAILED! => {
    "changed": false,
    "module_stderr": "Traceback (most recent call last):\n  File \"/usr/local/Cellar/python/3.7.4_1/Frameworks/Python.framework/Versions/3.7/lib/python3.7/urllib/request.py\", line 1317, in do_open\n    encode_chunked=req.has_header('Transfer-encoding'))\n  File \"/usr/local/Cellar/python/3.7.4_1/Frameworks/Python.framework/Versions/3.7/lib/python3.7/http/client.py\", line 1244, in request\n    self._send_request(method, url, body, headers, encode_chunked)\n  File \"/usr/local/Cellar/python/3.7.4_1/Frameworks/Python.framework/Versions/3.7/lib/python3.7/http/client.py\", line 1290, in _send_request\n    self.endheaders(body, encode_chunked=encode_chunked)\n  File \"/usr/local/Cellar/python/3.7.4_1/Frameworks/Python.framework/Versions/3.7/lib/python3.7/http/client.py\", line 1239, in endheaders\n    self._send_output(message_body, encode_chunked=encode_chunked)\n  File \"/usr/local/Cellar/python/3.7.4_1/Frameworks/Python.framework/Versions/3.7/lib/python3.7/http/client.py\", line 1026, in _send_output\n    self.send(msg)\n  File \"/usr/local/Cellar/python/3.7.4_1/Frameworks/Python.framework/Versions/3.7/lib/python3.7/http/client.py\", line 966, in send\n    self.connect()\n  File \"/var/folders/94/gcvyc1g9191_npwtrl55hsq54jxlgs/T/ansible_bigip_appsvcs_extension_payload_dxv7a4vm/ansible_bigip_appsvcs_extension_payload.zip/ansible/module_utils/urls.py\", line 430, in connect\n  File \"/usr/local/Cellar/python/3.7.4_1/Frameworks/Python.framework/Versions/3.7/lib/python3.7/ssl.py\", line 423, in wrap_socket\n    session=session\n  File \"/usr/local/Cellar/python/3.7.4_1/Frameworks/Python.framework/Versions/3.7/lib/python3.7/ssl.py\", line 870, in _create\n    self.do_handshake()\n  File \"/usr/local/Cellar/python/3.7.4_1/Frameworks/Python.framework/Versions/3.7/lib/python3.7/ssl.py\", line 1139, in do_handshake\n    self._sslobj.do_handshake()\nssl.SSLCertVerificationError: [SSL: CERTIFICATE_VERIFY_FAILED] certificate verify failed: self signed certificate (_ssl.c:1076)\n\nDuring handling of the above exception, another exception occurred:\n\nTraceback (most recent call last):\n  File \"<stdin>\", line 102, in <module>\n  File \"<stdin>\", line 94, in _ansiballz_main\n  File \"<stdin>\", line 40, in invoke_module\n  File \"/usr/local/Cellar/python/3.7.4_1/Frameworks/Python.framework/Versions/3.7/lib/python3.7/runpy.py\", line 205, in run_module\n    return _run_module_code(code, init_globals, run_name, mod_spec)\n  File \"/usr/local/Cellar/python/3.7.4_1/Frameworks/Python.framework/Versions/3.7/lib/python3.7/runpy.py\", line 96, in _run_module_code\n    mod_name, mod_spec, pkg_name, script_name)\n  File \"/usr/local/Cellar/python/3.7.4_1/Frameworks/Python.framework/Versions/3.7/lib/python3.7/runpy.py\", line 85, in _run_code\n    exec(code, run_globals)\n  File \"/var/folders/94/gcvyc1g9191_npwtrl55hsq54jxlgs/T/ansible_bigip_appsvcs_extension_payload_dxv7a4vm/ansible_bigip_appsvcs_extension_payload.zip/ansible/modules/network/f5/bigip_appsvcs_extension.py\", line 549, in <module>\n  File \"/var/folders/94/gcvyc1g9191_npwtrl55hsq54jxlgs/T/ansible_bigip_appsvcs_extension_payload_dxv7a4vm/ansible_bigip_appsvcs_extension_payload.zip/ansible/modules/network/f5/bigip_appsvcs_extension.py\", line 542, in main\n  File \"/var/folders/94/gcvyc1g9191_npwtrl55hsq54jxlgs/T/ansible_bigip_appsvcs_extension_payload_dxv7a4vm/ansible_bigip_appsvcs_extension_payload.zip/ansible/modules/network/f5/bigip_appsvcs_extension.py\", line 351, in exec_module\n  File \"/var/folders/94/gcvyc1g9191_npwtrl55hsq54jxlgs/T/ansible_bigip_appsvcs_extension_payload_dxv7a4vm/ansible_bigip_appsvcs_extension_payload.zip/ansible/modules/network/f5/bigip_appsvcs_extension.py\", line 362, in present\n  File \"/var/folders/94/gcvyc1g9191_npwtrl55hsq54jxlgs/T/ansible_bigip_appsvcs_extension_payload_dxv7a4vm/ansible_bigip_appsvcs_extension_payload.zip/ansible/modules/network/f5/bigip_appsvcs_extension.py\", line 461, in exists\n  File \"/var/folders/94/gcvyc1g9191_npwtrl55hsq54jxlgs/T/ansible_bigip_appsvcs_extension_payload_dxv7a4vm/ansible_bigip_appsvcs_extension_payload.zip/ansible/module_utils/network/f5/bigip.py\", line 34, in api\n  File \"/var/folders/94/gcvyc1g9191_npwtrl55hsq54jxlgs/T/ansible_bigip_appsvcs_extension_payload_dxv7a4vm/ansible_bigip_appsvcs_extension_payload.zip/ansible/module_utils/network/f5/bigip.py\", line 58, in connect_via_token_auth\n  File \"/var/folders/94/gcvyc1g9191_npwtrl55hsq54jxlgs/T/ansible_bigip_appsvcs_extension_payload_dxv7a4vm/ansible_bigip_appsvcs_extension_payload.zip/ansible/module_utils/network/f5/icontrol.py\", line 238, in post\n  File \"/var/folders/94/gcvyc1g9191_npwtrl55hsq54jxlgs/T/ansible_bigip_appsvcs_extension_payload_dxv7a4vm/ansible_bigip_appsvcs_extension_payload.zip/ansible/module_utils/network/f5/icontrol.py\", line 193, in send\n  File \"/var/folders/94/gcvyc1g9191_npwtrl55hsq54jxlgs/T/ansible_bigip_appsvcs_extension_payload_dxv7a4vm/ansible_bigip_appsvcs_extension_payload.zip/ansible/module_utils/urls.py\", line 1294, in open\n  File \"/usr/local/Cellar/python/3.7.4_1/Frameworks/Python.framework/Versions/3.7/lib/python3.7/urllib/request.py\", line 222, in urlopen\n    return opener.open(url, data, timeout)\n  File \"/usr/local/Cellar/python/3.7.4_1/Frameworks/Python.framework/Versions/3.7/lib/python3.7/urllib/request.py\", line 525, in open\n    response = self._open(req, data)\n  File \"/usr/local/Cellar/python/3.7.4_1/Frameworks/Python.framework/Versions/3.7/lib/python3.7/urllib/request.py\", line 543, in _open\n    '_open', req)\n  File \"/usr/local/Cellar/python/3.7.4_1/Frameworks/Python.framework/Versions/3.7/lib/python3.7/urllib/request.py\", line 503, in _call_chain\n    result = func(*args)\n  File \"/var/folders/94/gcvyc1g9191_npwtrl55hsq54jxlgs/T/ansible_bigip_appsvcs_extension_payload_dxv7a4vm/ansible_bigip_appsvcs_extension_payload.zip/ansible/module_utils/urls.py\", line 448, in https_open\n  File \"/usr/local/Cellar/python/3.7.4_1/Frameworks/Python.framework/Versions/3.7/lib/python3.7/urllib/request.py\", line 1319, in do_open\n    raise URLError(err)\nurllib.error.URLError: <urlopen error [SSL: CERTIFICATE_VERIFY_FAILED] certificate verify failed: self signed certificate (_ssl.c:1076)>\n",
    "module_stdout": "",
    "msg": "MODULE FAILURE\nSee stdout/stderr for the exact error",
    "rc": 1
}
2020-09-08 21:36:04,596 p=98176 u=ganti n=ansible | User interrupted execution
2020-09-08 21:36:16,168 p=98253 u=ganti n=ansible | ansible-playbook 2.9.5
  config file = /Users/ganti/Code/ansible-tower/ansible.cfg
  configured module search path = ['/Users/ganti/.ansible/plugins/modules', '/usr/share/ansible/plugins/modules']
  ansible python module location = /usr/local/lib/python3.7/site-packages/ansible
  executable location = /usr/local/bin/ansible-playbook
  python version = 3.7.4 (default, Sep  7 2019, 18:27:02) [Clang 10.0.1 (clang-1001.0.46.4)]
2020-09-08 21:36:16,168 p=98253 u=ganti n=ansible | Using /Users/ganti/Code/ansible-tower/ansible.cfg as config file
2020-09-08 21:36:16,174 p=98253 u=ganti n=ansible | host_list declined parsing /Users/ganti/Code/ansible-tower/inventory/dev/hosts as it did not pass its verify_file() method
2020-09-08 21:36:16,174 p=98253 u=ganti n=ansible | script declined parsing /Users/ganti/Code/ansible-tower/inventory/dev/hosts as it did not pass its verify_file() method
2020-09-08 21:36:16,175 p=98253 u=ganti n=ansible | auto declined parsing /Users/ganti/Code/ansible-tower/inventory/dev/hosts as it did not pass its verify_file() method
2020-09-08 21:36:16,177 p=98253 u=ganti n=ansible | [DEPRECATION WARNING]: The TRANSFORM_INVALID_GROUP_CHARS settings is set to allow bad characters in group names by default, this will change, but still be user 
configurable on deprecation. This feature will be removed in version 2.10. Deprecation warnings can be disabled by setting deprecation_warnings=False in 
ansible.cfg.
2020-09-08 21:36:16,177 p=98253 u=ganti n=ansible | [WARNING]: Invalid characters were found in group names but not replaced, use -vvvv to see details

2020-09-08 21:36:16,181 p=98253 u=ganti n=ansible | Parsed /Users/ganti/Code/ansible-tower/inventory/dev/hosts inventory source with ini plugin
2020-09-08 21:36:16,460 p=98253 u=ganti n=ansible | PLAYBOOK: app.yml ***********************************************************************************************************************************************
2020-09-08 21:36:16,460 p=98253 u=ganti n=ansible | 1 plays in app.yml
2020-09-08 21:36:16,461 p=98253 u=ganti n=ansible | PLAY [Big IP Operations] ****************************************************************************************************************************************
2020-09-08 21:36:16,468 p=98253 u=ganti n=ansible | META: ran handlers
2020-09-08 21:36:16,473 p=98253 u=ganti n=ansible | TASK [tcp : include_tasks] **************************************************************************************************************************************
2020-09-08 21:36:16,473 p=98253 u=ganti n=ansible | task path: /Users/ganti/Code/ansible-tower/roles/tcp/tasks/main.yml:1
2020-09-08 21:36:16,473 p=98253 u=ganti n=ansible | Tuesday 08 September 2020  21:36:16 -0400 (0:00:00.024)       0:00:00.025 ***** 
2020-09-08 21:36:16,536 p=98253 u=ganti n=ansible | included: /Users/ganti/Code/ansible-tower/roles/tcp/tasks/tcp.yml for localhost
2020-09-08 21:36:16,542 p=98253 u=ganti n=ansible | TASK [tcp : Deploy an tcp app service configuration] ************************************************************************************************************
2020-09-08 21:36:16,542 p=98253 u=ganti n=ansible | task path: /Users/ganti/Code/ansible-tower/roles/tcp/tasks/tcp.yml:1
2020-09-08 21:36:16,542 p=98253 u=ganti n=ansible | Tuesday 08 September 2020  21:36:16 -0400 (0:00:00.068)       0:00:00.093 ***** 
2020-09-08 21:36:16,770 p=98258 u=ganti n=ansible | Using module file /usr/local/lib/python3.7/site-packages/ansible/modules/network/f5/bigip_appsvcs_extension.py
2020-09-08 21:36:16,771 p=98258 u=ganti n=ansible | Pipelining is enabled.
2020-09-08 21:36:16,771 p=98258 u=ganti n=ansible | <localhost> ESTABLISH LOCAL CONNECTION FOR USER: ganti
2020-09-08 21:36:16,772 p=98258 u=ganti n=ansible | <localhost> EXEC /bin/sh -c '/usr/local/opt/python/bin/python3.7 && sleep 0'
2020-09-08 21:36:17,235 p=98253 u=ganti n=ansible | The full traceback is:
Traceback (most recent call last):
  File "/usr/local/Cellar/python/3.7.4_1/Frameworks/Python.framework/Versions/3.7/lib/python3.7/urllib/request.py", line 1317, in do_open
    encode_chunked=req.has_header('Transfer-encoding'))
  File "/usr/local/Cellar/python/3.7.4_1/Frameworks/Python.framework/Versions/3.7/lib/python3.7/http/client.py", line 1244, in request
    self._send_request(method, url, body, headers, encode_chunked)
  File "/usr/local/Cellar/python/3.7.4_1/Frameworks/Python.framework/Versions/3.7/lib/python3.7/http/client.py", line 1290, in _send_request
    self.endheaders(body, encode_chunked=encode_chunked)
  File "/usr/local/Cellar/python/3.7.4_1/Frameworks/Python.framework/Versions/3.7/lib/python3.7/http/client.py", line 1239, in endheaders
    self._send_output(message_body, encode_chunked=encode_chunked)
  File "/usr/local/Cellar/python/3.7.4_1/Frameworks/Python.framework/Versions/3.7/lib/python3.7/http/client.py", line 1026, in _send_output
    self.send(msg)
  File "/usr/local/Cellar/python/3.7.4_1/Frameworks/Python.framework/Versions/3.7/lib/python3.7/http/client.py", line 966, in send
    self.connect()
  File "/var/folders/94/gcvyc1g9191_npwtrl55hsq54jxlgs/T/ansible_bigip_appsvcs_extension_payload_el4s_sly/ansible_bigip_appsvcs_extension_payload.zip/ansible/module_utils/urls.py", line 430, in connect
  File "/usr/local/Cellar/python/3.7.4_1/Frameworks/Python.framework/Versions/3.7/lib/python3.7/ssl.py", line 423, in wrap_socket
    session=session
  File "/usr/local/Cellar/python/3.7.4_1/Frameworks/Python.framework/Versions/3.7/lib/python3.7/ssl.py", line 870, in _create
    self.do_handshake()
  File "/usr/local/Cellar/python/3.7.4_1/Frameworks/Python.framework/Versions/3.7/lib/python3.7/ssl.py", line 1139, in do_handshake
    self._sslobj.do_handshake()
ssl.SSLCertVerificationError: [SSL: CERTIFICATE_VERIFY_FAILED] certificate verify failed: self signed certificate (_ssl.c:1076)

During handling of the above exception, another exception occurred:

Traceback (most recent call last):
  File "<stdin>", line 102, in <module>
  File "<stdin>", line 94, in _ansiballz_main
  File "<stdin>", line 40, in invoke_module
  File "/usr/local/Cellar/python/3.7.4_1/Frameworks/Python.framework/Versions/3.7/lib/python3.7/runpy.py", line 205, in run_module
    return _run_module_code(code, init_globals, run_name, mod_spec)
  File "/usr/local/Cellar/python/3.7.4_1/Frameworks/Python.framework/Versions/3.7/lib/python3.7/runpy.py", line 96, in _run_module_code
    mod_name, mod_spec, pkg_name, script_name)
  File "/usr/local/Cellar/python/3.7.4_1/Frameworks/Python.framework/Versions/3.7/lib/python3.7/runpy.py", line 85, in _run_code
    exec(code, run_globals)
  File "/var/folders/94/gcvyc1g9191_npwtrl55hsq54jxlgs/T/ansible_bigip_appsvcs_extension_payload_el4s_sly/ansible_bigip_appsvcs_extension_payload.zip/ansible/modules/network/f5/bigip_appsvcs_extension.py", line 549, in <module>
  File "/var/folders/94/gcvyc1g9191_npwtrl55hsq54jxlgs/T/ansible_bigip_appsvcs_extension_payload_el4s_sly/ansible_bigip_appsvcs_extension_payload.zip/ansible/modules/network/f5/bigip_appsvcs_extension.py", line 542, in main
  File "/var/folders/94/gcvyc1g9191_npwtrl55hsq54jxlgs/T/ansible_bigip_appsvcs_extension_payload_el4s_sly/ansible_bigip_appsvcs_extension_payload.zip/ansible/modules/network/f5/bigip_appsvcs_extension.py", line 351, in exec_module
  File "/var/folders/94/gcvyc1g9191_npwtrl55hsq54jxlgs/T/ansible_bigip_appsvcs_extension_payload_el4s_sly/ansible_bigip_appsvcs_extension_payload.zip/ansible/modules/network/f5/bigip_appsvcs_extension.py", line 362, in present
  File "/var/folders/94/gcvyc1g9191_npwtrl55hsq54jxlgs/T/ansible_bigip_appsvcs_extension_payload_el4s_sly/ansible_bigip_appsvcs_extension_payload.zip/ansible/modules/network/f5/bigip_appsvcs_extension.py", line 461, in exists
  File "/var/folders/94/gcvyc1g9191_npwtrl55hsq54jxlgs/T/ansible_bigip_appsvcs_extension_payload_el4s_sly/ansible_bigip_appsvcs_extension_payload.zip/ansible/module_utils/network/f5/bigip.py", line 34, in api
  File "/var/folders/94/gcvyc1g9191_npwtrl55hsq54jxlgs/T/ansible_bigip_appsvcs_extension_payload_el4s_sly/ansible_bigip_appsvcs_extension_payload.zip/ansible/module_utils/network/f5/bigip.py", line 58, in connect_via_token_auth
  File "/var/folders/94/gcvyc1g9191_npwtrl55hsq54jxlgs/T/ansible_bigip_appsvcs_extension_payload_el4s_sly/ansible_bigip_appsvcs_extension_payload.zip/ansible/module_utils/network/f5/icontrol.py", line 238, in post
  File "/var/folders/94/gcvyc1g9191_npwtrl55hsq54jxlgs/T/ansible_bigip_appsvcs_extension_payload_el4s_sly/ansible_bigip_appsvcs_extension_payload.zip/ansible/module_utils/network/f5/icontrol.py", line 193, in send
  File "/var/folders/94/gcvyc1g9191_npwtrl55hsq54jxlgs/T/ansible_bigip_appsvcs_extension_payload_el4s_sly/ansible_bigip_appsvcs_extension_payload.zip/ansible/module_utils/urls.py", line 1294, in open
  File "/usr/local/Cellar/python/3.7.4_1/Frameworks/Python.framework/Versions/3.7/lib/python3.7/urllib/request.py", line 222, in urlopen
    return opener.open(url, data, timeout)
  File "/usr/local/Cellar/python/3.7.4_1/Frameworks/Python.framework/Versions/3.7/lib/python3.7/urllib/request.py", line 525, in open
    response = self._open(req, data)
  File "/usr/local/Cellar/python/3.7.4_1/Frameworks/Python.framework/Versions/3.7/lib/python3.7/urllib/request.py", line 543, in _open
    '_open', req)
  File "/usr/local/Cellar/python/3.7.4_1/Frameworks/Python.framework/Versions/3.7/lib/python3.7/urllib/request.py", line 503, in _call_chain
    result = func(*args)
  File "/var/folders/94/gcvyc1g9191_npwtrl55hsq54jxlgs/T/ansible_bigip_appsvcs_extension_payload_el4s_sly/ansible_bigip_appsvcs_extension_payload.zip/ansible/module_utils/urls.py", line 448, in https_open
  File "/usr/local/Cellar/python/3.7.4_1/Frameworks/Python.framework/Versions/3.7/lib/python3.7/urllib/request.py", line 1319, in do_open
    raise URLError(err)
urllib.error.URLError: <urlopen error [SSL: CERTIFICATE_VERIFY_FAILED] certificate verify failed: self signed certificate (_ssl.c:1076)>

2020-09-08 21:36:17,253 p=98253 u=ganti n=ansible | fatal: [localhost -> localhost]: FAILED! => {
    "changed": false,
    "module_stderr": "Traceback (most recent call last):\n  File \"/usr/local/Cellar/python/3.7.4_1/Frameworks/Python.framework/Versions/3.7/lib/python3.7/urllib/request.py\", line 1317, in do_open\n    encode_chunked=req.has_header('Transfer-encoding'))\n  File \"/usr/local/Cellar/python/3.7.4_1/Frameworks/Python.framework/Versions/3.7/lib/python3.7/http/client.py\", line 1244, in request\n    self._send_request(method, url, body, headers, encode_chunked)\n  File \"/usr/local/Cellar/python/3.7.4_1/Frameworks/Python.framework/Versions/3.7/lib/python3.7/http/client.py\", line 1290, in _send_request\n    self.endheaders(body, encode_chunked=encode_chunked)\n  File \"/usr/local/Cellar/python/3.7.4_1/Frameworks/Python.framework/Versions/3.7/lib/python3.7/http/client.py\", line 1239, in endheaders\n    self._send_output(message_body, encode_chunked=encode_chunked)\n  File \"/usr/local/Cellar/python/3.7.4_1/Frameworks/Python.framework/Versions/3.7/lib/python3.7/http/client.py\", line 1026, in _send_output\n    self.send(msg)\n  File \"/usr/local/Cellar/python/3.7.4_1/Frameworks/Python.framework/Versions/3.7/lib/python3.7/http/client.py\", line 966, in send\n    self.connect()\n  File \"/var/folders/94/gcvyc1g9191_npwtrl55hsq54jxlgs/T/ansible_bigip_appsvcs_extension_payload_el4s_sly/ansible_bigip_appsvcs_extension_payload.zip/ansible/module_utils/urls.py\", line 430, in connect\n  File \"/usr/local/Cellar/python/3.7.4_1/Frameworks/Python.framework/Versions/3.7/lib/python3.7/ssl.py\", line 423, in wrap_socket\n    session=session\n  File \"/usr/local/Cellar/python/3.7.4_1/Frameworks/Python.framework/Versions/3.7/lib/python3.7/ssl.py\", line 870, in _create\n    self.do_handshake()\n  File \"/usr/local/Cellar/python/3.7.4_1/Frameworks/Python.framework/Versions/3.7/lib/python3.7/ssl.py\", line 1139, in do_handshake\n    self._sslobj.do_handshake()\nssl.SSLCertVerificationError: [SSL: CERTIFICATE_VERIFY_FAILED] certificate verify failed: self signed certificate (_ssl.c:1076)\n\nDuring handling of the above exception, another exception occurred:\n\nTraceback (most recent call last):\n  File \"<stdin>\", line 102, in <module>\n  File \"<stdin>\", line 94, in _ansiballz_main\n  File \"<stdin>\", line 40, in invoke_module\n  File \"/usr/local/Cellar/python/3.7.4_1/Frameworks/Python.framework/Versions/3.7/lib/python3.7/runpy.py\", line 205, in run_module\n    return _run_module_code(code, init_globals, run_name, mod_spec)\n  File \"/usr/local/Cellar/python/3.7.4_1/Frameworks/Python.framework/Versions/3.7/lib/python3.7/runpy.py\", line 96, in _run_module_code\n    mod_name, mod_spec, pkg_name, script_name)\n  File \"/usr/local/Cellar/python/3.7.4_1/Frameworks/Python.framework/Versions/3.7/lib/python3.7/runpy.py\", line 85, in _run_code\n    exec(code, run_globals)\n  File \"/var/folders/94/gcvyc1g9191_npwtrl55hsq54jxlgs/T/ansible_bigip_appsvcs_extension_payload_el4s_sly/ansible_bigip_appsvcs_extension_payload.zip/ansible/modules/network/f5/bigip_appsvcs_extension.py\", line 549, in <module>\n  File \"/var/folders/94/gcvyc1g9191_npwtrl55hsq54jxlgs/T/ansible_bigip_appsvcs_extension_payload_el4s_sly/ansible_bigip_appsvcs_extension_payload.zip/ansible/modules/network/f5/bigip_appsvcs_extension.py\", line 542, in main\n  File \"/var/folders/94/gcvyc1g9191_npwtrl55hsq54jxlgs/T/ansible_bigip_appsvcs_extension_payload_el4s_sly/ansible_bigip_appsvcs_extension_payload.zip/ansible/modules/network/f5/bigip_appsvcs_extension.py\", line 351, in exec_module\n  File \"/var/folders/94/gcvyc1g9191_npwtrl55hsq54jxlgs/T/ansible_bigip_appsvcs_extension_payload_el4s_sly/ansible_bigip_appsvcs_extension_payload.zip/ansible/modules/network/f5/bigip_appsvcs_extension.py\", line 362, in present\n  File \"/var/folders/94/gcvyc1g9191_npwtrl55hsq54jxlgs/T/ansible_bigip_appsvcs_extension_payload_el4s_sly/ansible_bigip_appsvcs_extension_payload.zip/ansible/modules/network/f5/bigip_appsvcs_extension.py\", line 461, in exists\n  File \"/var/folders/94/gcvyc1g9191_npwtrl55hsq54jxlgs/T/ansible_bigip_appsvcs_extension_payload_el4s_sly/ansible_bigip_appsvcs_extension_payload.zip/ansible/module_utils/network/f5/bigip.py\", line 34, in api\n  File \"/var/folders/94/gcvyc1g9191_npwtrl55hsq54jxlgs/T/ansible_bigip_appsvcs_extension_payload_el4s_sly/ansible_bigip_appsvcs_extension_payload.zip/ansible/module_utils/network/f5/bigip.py\", line 58, in connect_via_token_auth\n  File \"/var/folders/94/gcvyc1g9191_npwtrl55hsq54jxlgs/T/ansible_bigip_appsvcs_extension_payload_el4s_sly/ansible_bigip_appsvcs_extension_payload.zip/ansible/module_utils/network/f5/icontrol.py\", line 238, in post\n  File \"/var/folders/94/gcvyc1g9191_npwtrl55hsq54jxlgs/T/ansible_bigip_appsvcs_extension_payload_el4s_sly/ansible_bigip_appsvcs_extension_payload.zip/ansible/module_utils/network/f5/icontrol.py\", line 193, in send\n  File \"/var/folders/94/gcvyc1g9191_npwtrl55hsq54jxlgs/T/ansible_bigip_appsvcs_extension_payload_el4s_sly/ansible_bigip_appsvcs_extension_payload.zip/ansible/module_utils/urls.py\", line 1294, in open\n  File \"/usr/local/Cellar/python/3.7.4_1/Frameworks/Python.framework/Versions/3.7/lib/python3.7/urllib/request.py\", line 222, in urlopen\n    return opener.open(url, data, timeout)\n  File \"/usr/local/Cellar/python/3.7.4_1/Frameworks/Python.framework/Versions/3.7/lib/python3.7/urllib/request.py\", line 525, in open\n    response = self._open(req, data)\n  File \"/usr/local/Cellar/python/3.7.4_1/Frameworks/Python.framework/Versions/3.7/lib/python3.7/urllib/request.py\", line 543, in _open\n    '_open', req)\n  File \"/usr/local/Cellar/python/3.7.4_1/Frameworks/Python.framework/Versions/3.7/lib/python3.7/urllib/request.py\", line 503, in _call_chain\n    result = func(*args)\n  File \"/var/folders/94/gcvyc1g9191_npwtrl55hsq54jxlgs/T/ansible_bigip_appsvcs_extension_payload_el4s_sly/ansible_bigip_appsvcs_extension_payload.zip/ansible/module_utils/urls.py\", line 448, in https_open\n  File \"/usr/local/Cellar/python/3.7.4_1/Frameworks/Python.framework/Versions/3.7/lib/python3.7/urllib/request.py\", line 1319, in do_open\n    raise URLError(err)\nurllib.error.URLError: <urlopen error [SSL: CERTIFICATE_VERIFY_FAILED] certificate verify failed: self signed certificate (_ssl.c:1076)>\n",
    "module_stdout": "",
    "msg": "MODULE FAILURE\nSee stdout/stderr for the exact error",
    "rc": 1
}
2020-09-08 21:37:07,227 p=98253 u=ganti n=ansible | User interrupted execution
2020-09-08 21:37:15,185 p=98434 u=ganti n=ansible | ansible-playbook 2.9.5
  config file = /Users/ganti/Code/ansible-tower/ansible.cfg
  configured module search path = ['/Users/ganti/.ansible/plugins/modules', '/usr/share/ansible/plugins/modules']
  ansible python module location = /usr/local/lib/python3.7/site-packages/ansible
  executable location = /usr/local/bin/ansible-playbook
  python version = 3.7.4 (default, Sep  7 2019, 18:27:02) [Clang 10.0.1 (clang-1001.0.46.4)]
2020-09-08 21:37:15,185 p=98434 u=ganti n=ansible | Using /Users/ganti/Code/ansible-tower/ansible.cfg as config file
2020-09-08 21:37:15,190 p=98434 u=ganti n=ansible | host_list declined parsing /Users/ganti/Code/ansible-tower/inventory/dev/hosts as it did not pass its verify_file() method
2020-09-08 21:37:15,191 p=98434 u=ganti n=ansible | script declined parsing /Users/ganti/Code/ansible-tower/inventory/dev/hosts as it did not pass its verify_file() method
2020-09-08 21:37:15,191 p=98434 u=ganti n=ansible | auto declined parsing /Users/ganti/Code/ansible-tower/inventory/dev/hosts as it did not pass its verify_file() method
2020-09-08 21:37:15,193 p=98434 u=ganti n=ansible | [DEPRECATION WARNING]: The TRANSFORM_INVALID_GROUP_CHARS settings is set to allow bad characters in group names by default, this will change, but still be user 
configurable on deprecation. This feature will be removed in version 2.10. Deprecation warnings can be disabled by setting deprecation_warnings=False in 
ansible.cfg.
2020-09-08 21:37:15,193 p=98434 u=ganti n=ansible | [WARNING]: Invalid characters were found in group names but not replaced, use -vvvv to see details

2020-09-08 21:37:15,197 p=98434 u=ganti n=ansible | Parsed /Users/ganti/Code/ansible-tower/inventory/dev/hosts inventory source with ini plugin
2020-09-08 21:37:15,518 p=98434 u=ganti n=ansible | PLAYBOOK: app.yml ***********************************************************************************************************************************************
2020-09-08 21:37:15,518 p=98434 u=ganti n=ansible | 1 plays in app.yml
2020-09-08 21:37:15,520 p=98434 u=ganti n=ansible | PLAY [Big IP Operations] ****************************************************************************************************************************************
2020-09-08 21:37:15,529 p=98434 u=ganti n=ansible | META: ran handlers
2020-09-08 21:37:15,534 p=98434 u=ganti n=ansible | TASK [tcp : include_tasks] **************************************************************************************************************************************
2020-09-08 21:37:15,534 p=98434 u=ganti n=ansible | task path: /Users/ganti/Code/ansible-tower/roles/tcp/tasks/main.yml:1
2020-09-08 21:37:15,535 p=98434 u=ganti n=ansible | Tuesday 08 September 2020  21:37:15 -0400 (0:00:00.029)       0:00:00.029 ***** 
2020-09-08 21:37:15,605 p=98434 u=ganti n=ansible | included: /Users/ganti/Code/ansible-tower/roles/tcp/tasks/tcp.yml for localhost
2020-09-08 21:37:15,611 p=98434 u=ganti n=ansible | TASK [tcp : Deploy an tcp app service configuration] ************************************************************************************************************
2020-09-08 21:37:15,611 p=98434 u=ganti n=ansible | task path: /Users/ganti/Code/ansible-tower/roles/tcp/tasks/tcp.yml:1
2020-09-08 21:37:15,611 p=98434 u=ganti n=ansible | Tuesday 08 September 2020  21:37:15 -0400 (0:00:00.076)       0:00:00.105 ***** 
2020-09-08 21:37:15,833 p=98443 u=ganti n=ansible | Using module file /usr/local/lib/python3.7/site-packages/ansible/modules/network/f5/bigip_appsvcs_extension.py
2020-09-08 21:37:15,834 p=98443 u=ganti n=ansible | Pipelining is enabled.
2020-09-08 21:37:15,834 p=98443 u=ganti n=ansible | <localhost> ESTABLISH LOCAL CONNECTION FOR USER: ganti
2020-09-08 21:37:15,834 p=98443 u=ganti n=ansible | <localhost> EXEC /bin/sh -c '/usr/local/opt/python/bin/python3.7 && sleep 0'
2020-09-08 21:37:21,250 p=98434 u=ganti n=ansible | The full traceback is:
  File "/var/folders/94/gcvyc1g9191_npwtrl55hsq54jxlgs/T/ansible_bigip_appsvcs_extension_payload_fzfxmbti/ansible_bigip_appsvcs_extension_payload.zip/ansible/modules/network/f5/bigip_appsvcs_extension.py", line 542, in main
  File "/var/folders/94/gcvyc1g9191_npwtrl55hsq54jxlgs/T/ansible_bigip_appsvcs_extension_payload_fzfxmbti/ansible_bigip_appsvcs_extension_payload.zip/ansible/modules/network/f5/bigip_appsvcs_extension.py", line 351, in exec_module
  File "/var/folders/94/gcvyc1g9191_npwtrl55hsq54jxlgs/T/ansible_bigip_appsvcs_extension_payload_fzfxmbti/ansible_bigip_appsvcs_extension_payload.zip/ansible/modules/network/f5/bigip_appsvcs_extension.py", line 362, in present
  File "/var/folders/94/gcvyc1g9191_npwtrl55hsq54jxlgs/T/ansible_bigip_appsvcs_extension_payload_fzfxmbti/ansible_bigip_appsvcs_extension_payload.zip/ansible/modules/network/f5/bigip_appsvcs_extension.py", line 461, in exists
  File "/var/folders/94/gcvyc1g9191_npwtrl55hsq54jxlgs/T/ansible_bigip_appsvcs_extension_payload_fzfxmbti/ansible_bigip_appsvcs_extension_payload.zip/ansible/module_utils/network/f5/bigip.py", line 38, in api
    raise F5ModuleError(err)

2020-09-08 21:37:21,266 p=98434 u=ganti n=ansible | fatal: [localhost -> localhost]: FAILED! => {
    "changed": false,
    "invocation": {
        "module_args": {
            "content": {
                "action": "deploy",
                "class": "AS3",
                "declaration": {
                    "Sample_03": {
                        "A1": {
                            "class": "Application",
                            "service": {
                                "class": "Service_TCP",
                                "pool": "svc_pool",
                                "virtualAddresses": [
                                    "10.0.5.10"
                                ],
                                "virtualPort": 1344
                            },
                            "svc_pool": {
                                "class": "Pool",
                                "members": [
                                    {
                                        "serverAddresses": [
                                            "192.0.5.10",
                                            "192.0.5.11"
                                        ],
                                        "servicePort": 1344
                                    }
                                ],
                                "monitors": [
                                    "tcp"
                                ]
                            }
                        },
                        "class": "Tenant"
                    },
                    "class": "ADC",
                    "id": "789ghi",
                    "label": "Sample 3",
                    "remark": "TCP app",
                    "schemaVersion": "3.20.0"
                },
                "persist": true
            },
            "force": false,
            "provider": {
                "auth_provider": null,
                "password": "VALUE_SPECIFIED_IN_NO_LOG_PARAMETER",
                "server": "54.89.34.114",
                "server_port": 8443,
                "ssh_keyfile": null,
                "timeout": null,
                "transport": "rest",
                "user": "admin",
                "validate_certs": false
            },
            "state": "present",
            "tenants": null
        }
    },
    "msg": "b'<!DOCTYPE HTML PUBLIC \"-//IETF//DTD HTML 2.0//EN\">\\n<html><head>\\n<title>401 Unauthorized</title>\\n</head><body>\\n<h1>Unauthorized</h1>\\n<p>This server could not verify that you\\nare authorized to access the document\\nrequested.  Either you supplied the wrong\\ncredentials (e.g., bad password), or your\\nbrowser doesn\\'t understand how to supply\\nthe credentials required.</p>\\n</body></html>\\n'"
}
2020-09-08 21:37:41,458 p=98434 u=ganti n=ansible | User interrupted execution
2020-09-08 21:41:02,085 p=99015 u=ganti n=ansible | ansible-playbook 2.9.5
  config file = /Users/ganti/Code/ansible-tower/ansible.cfg
  configured module search path = ['/Users/ganti/.ansible/plugins/modules', '/usr/share/ansible/plugins/modules']
  ansible python module location = /usr/local/lib/python3.7/site-packages/ansible
  executable location = /usr/local/bin/ansible-playbook
  python version = 3.7.4 (default, Sep  7 2019, 18:27:02) [Clang 10.0.1 (clang-1001.0.46.4)]
2020-09-08 21:41:02,085 p=99015 u=ganti n=ansible | Using /Users/ganti/Code/ansible-tower/ansible.cfg as config file
2020-09-08 21:41:02,094 p=99015 u=ganti n=ansible | host_list declined parsing /Users/ganti/Code/ansible-tower/inventory/dev/hosts as it did not pass its verify_file() method
2020-09-08 21:41:02,095 p=99015 u=ganti n=ansible | script declined parsing /Users/ganti/Code/ansible-tower/inventory/dev/hosts as it did not pass its verify_file() method
2020-09-08 21:41:02,095 p=99015 u=ganti n=ansible | auto declined parsing /Users/ganti/Code/ansible-tower/inventory/dev/hosts as it did not pass its verify_file() method
2020-09-08 21:41:02,099 p=99015 u=ganti n=ansible | [DEPRECATION WARNING]: The TRANSFORM_INVALID_GROUP_CHARS settings is set to allow bad characters in group names by default, this will change, but still be user 
configurable on deprecation. This feature will be removed in version 2.10. Deprecation warnings can be disabled by setting deprecation_warnings=False in 
ansible.cfg.
2020-09-08 21:41:02,099 p=99015 u=ganti n=ansible | [WARNING]: Invalid characters were found in group names but not replaced, use -vvvv to see details

2020-09-08 21:41:02,099 p=99015 u=ganti n=ansible | Parsed /Users/ganti/Code/ansible-tower/inventory/dev/hosts inventory source with ini plugin
2020-09-08 21:41:02,477 p=99015 u=ganti n=ansible | PLAYBOOK: app.yml ***********************************************************************************************************************************************
2020-09-08 21:41:02,477 p=99015 u=ganti n=ansible | 1 plays in app.yml
2020-09-08 21:41:02,478 p=99015 u=ganti n=ansible | PLAY [Big IP Operations] ****************************************************************************************************************************************
2020-09-08 21:41:02,487 p=99015 u=ganti n=ansible | META: ran handlers
2020-09-08 21:41:02,492 p=99015 u=ganti n=ansible | TASK [tcp : include_tasks] **************************************************************************************************************************************
2020-09-08 21:41:02,492 p=99015 u=ganti n=ansible | task path: /Users/ganti/Code/ansible-tower/roles/tcp/tasks/main.yml:1
2020-09-08 21:41:02,493 p=99015 u=ganti n=ansible | Tuesday 08 September 2020  21:41:02 -0400 (0:00:00.028)       0:00:00.028 ***** 
2020-09-08 21:41:02,558 p=99015 u=ganti n=ansible | included: /Users/ganti/Code/ansible-tower/roles/tcp/tasks/tcp.yml for localhost
2020-09-08 21:41:02,563 p=99015 u=ganti n=ansible | TASK [tcp : Deploy an tcp app service configuration] ************************************************************************************************************
2020-09-08 21:41:02,563 p=99015 u=ganti n=ansible | task path: /Users/ganti/Code/ansible-tower/roles/tcp/tasks/tcp.yml:1
2020-09-08 21:41:02,563 p=99015 u=ganti n=ansible | Tuesday 08 September 2020  21:41:02 -0400 (0:00:00.070)       0:00:00.099 ***** 
2020-09-08 21:41:02,833 p=99020 u=ganti n=ansible | Using module file /usr/local/lib/python3.7/site-packages/ansible/modules/network/f5/bigip_appsvcs_extension.py
2020-09-08 21:41:02,834 p=99020 u=ganti n=ansible | Pipelining is enabled.
2020-09-08 21:41:02,834 p=99020 u=ganti n=ansible | <localhost> ESTABLISH LOCAL CONNECTION FOR USER: ganti
2020-09-08 21:41:02,835 p=99020 u=ganti n=ansible | <localhost> EXEC /bin/sh -c '/usr/local/opt/python/bin/python3.7 && sleep 0'
2020-09-08 21:41:07,777 p=99015 u=ganti n=ansible | The full traceback is:
  File "/var/folders/94/gcvyc1g9191_npwtrl55hsq54jxlgs/T/ansible_bigip_appsvcs_extension_payload_anxhx5n6/ansible_bigip_appsvcs_extension_payload.zip/ansible/modules/network/f5/bigip_appsvcs_extension.py", line 542, in main
  File "/var/folders/94/gcvyc1g9191_npwtrl55hsq54jxlgs/T/ansible_bigip_appsvcs_extension_payload_anxhx5n6/ansible_bigip_appsvcs_extension_payload.zip/ansible/modules/network/f5/bigip_appsvcs_extension.py", line 351, in exec_module
  File "/var/folders/94/gcvyc1g9191_npwtrl55hsq54jxlgs/T/ansible_bigip_appsvcs_extension_payload_anxhx5n6/ansible_bigip_appsvcs_extension_payload.zip/ansible/modules/network/f5/bigip_appsvcs_extension.py", line 362, in present
  File "/var/folders/94/gcvyc1g9191_npwtrl55hsq54jxlgs/T/ansible_bigip_appsvcs_extension_payload_anxhx5n6/ansible_bigip_appsvcs_extension_payload.zip/ansible/modules/network/f5/bigip_appsvcs_extension.py", line 461, in exists
  File "/var/folders/94/gcvyc1g9191_npwtrl55hsq54jxlgs/T/ansible_bigip_appsvcs_extension_payload_anxhx5n6/ansible_bigip_appsvcs_extension_payload.zip/ansible/module_utils/network/f5/bigip.py", line 38, in api
    raise F5ModuleError(err)

2020-09-08 21:41:07,790 p=99015 u=ganti n=ansible | fatal: [localhost -> localhost]: FAILED! => {
    "changed": false,
    "invocation": {
        "module_args": {
            "content": {
                "action": "deploy",
                "class": "AS3",
                "declaration": {
                    "Sample_03": {
                        "A1": {
                            "class": "Application",
                            "service": {
                                "class": "Service_TCP",
                                "pool": "svc_pool",
                                "virtualAddresses": [
                                    "10.0.5.10"
                                ],
                                "virtualPort": 1344
                            },
                            "svc_pool": {
                                "class": "Pool",
                                "members": [
                                    {
                                        "serverAddresses": [
                                            "192.0.5.10",
                                            "192.0.5.11"
                                        ],
                                        "servicePort": 1344
                                    }
                                ],
                                "monitors": [
                                    "tcp"
                                ]
                            }
                        },
                        "class": "Tenant"
                    },
                    "class": "ADC",
                    "id": "789ghi",
                    "label": "Sample 3",
                    "remark": "TCP app",
                    "schemaVersion": "3.20.0"
                },
                "persist": true
            },
            "force": false,
            "provider": {
                "auth_provider": null,
                "password": "VALUE_SPECIFIED_IN_NO_LOG_PARAMETER",
                "server": "54.89.34.114",
                "server_port": 8443,
                "ssh_keyfile": null,
                "timeout": null,
                "transport": "rest",
                "user": "admin",
                "validate_certs": false
            },
            "state": "present",
            "tenants": null
        }
    },
    "msg": "b'<!DOCTYPE HTML PUBLIC \"-//IETF//DTD HTML 2.0//EN\">\\n<html><head>\\n<title>401 Unauthorized</title>\\n</head><body>\\n<h1>Unauthorized</h1>\\n<p>This server could not verify that you\\nare authorized to access the document\\nrequested.  Either you supplied the wrong\\ncredentials (e.g., bad password), or your\\nbrowser doesn\\'t understand how to supply\\nthe credentials required.</p>\\n</body></html>\\n'"
}
2020-09-08 21:42:13,126 p=99015 u=ganti n=ansible | User interrupted execution
2020-09-08 21:43:14,165 p=99384 u=ganti n=ansible | ansible-playbook 2.9.5
  config file = /Users/ganti/Code/ansible-tower/ansible.cfg
  configured module search path = ['/Users/ganti/.ansible/plugins/modules', '/usr/share/ansible/plugins/modules']
  ansible python module location = /usr/local/lib/python3.7/site-packages/ansible
  executable location = /usr/local/bin/ansible-playbook
  python version = 3.7.4 (default, Sep  7 2019, 18:27:02) [Clang 10.0.1 (clang-1001.0.46.4)]
2020-09-08 21:43:14,165 p=99384 u=ganti n=ansible | Using /Users/ganti/Code/ansible-tower/ansible.cfg as config file
2020-09-08 21:43:14,174 p=99384 u=ganti n=ansible | host_list declined parsing /Users/ganti/Code/ansible-tower/inventory/dev/hosts as it did not pass its verify_file() method
2020-09-08 21:43:14,175 p=99384 u=ganti n=ansible | script declined parsing /Users/ganti/Code/ansible-tower/inventory/dev/hosts as it did not pass its verify_file() method
2020-09-08 21:43:14,175 p=99384 u=ganti n=ansible | auto declined parsing /Users/ganti/Code/ansible-tower/inventory/dev/hosts as it did not pass its verify_file() method
2020-09-08 21:43:14,179 p=99384 u=ganti n=ansible | [DEPRECATION WARNING]: The TRANSFORM_INVALID_GROUP_CHARS settings is set to allow bad characters in group names by default, this will change, but still be user 
configurable on deprecation. This feature will be removed in version 2.10. Deprecation warnings can be disabled by setting deprecation_warnings=False in 
ansible.cfg.
2020-09-08 21:43:14,179 p=99384 u=ganti n=ansible | [WARNING]: Invalid characters were found in group names but not replaced, use -vvvv to see details

2020-09-08 21:43:14,179 p=99384 u=ganti n=ansible | Parsed /Users/ganti/Code/ansible-tower/inventory/dev/hosts inventory source with ini plugin
2020-09-08 21:43:14,546 p=99384 u=ganti n=ansible | PLAYBOOK: app.yml ***********************************************************************************************************************************************
2020-09-08 21:43:14,546 p=99384 u=ganti n=ansible | 1 plays in app.yml
2020-09-08 21:43:14,548 p=99384 u=ganti n=ansible | PLAY [Big IP Operations] ****************************************************************************************************************************************
2020-09-08 21:43:14,556 p=99384 u=ganti n=ansible | META: ran handlers
2020-09-08 21:43:14,562 p=99384 u=ganti n=ansible | TASK [tcp : include_tasks] **************************************************************************************************************************************
2020-09-08 21:43:14,562 p=99384 u=ganti n=ansible | task path: /Users/ganti/Code/ansible-tower/roles/tcp/tasks/main.yml:1
2020-09-08 21:43:14,562 p=99384 u=ganti n=ansible | Tuesday 08 September 2020  21:43:14 -0400 (0:00:00.028)       0:00:00.028 ***** 
2020-09-08 21:43:14,628 p=99384 u=ganti n=ansible | included: /Users/ganti/Code/ansible-tower/roles/tcp/tasks/tcp.yml for localhost
2020-09-08 21:43:14,633 p=99384 u=ganti n=ansible | TASK [tcp : Deploy an tcp app service configuration] ************************************************************************************************************
2020-09-08 21:43:14,633 p=99384 u=ganti n=ansible | task path: /Users/ganti/Code/ansible-tower/roles/tcp/tasks/tcp.yml:1
2020-09-08 21:43:14,633 p=99384 u=ganti n=ansible | Tuesday 08 September 2020  21:43:14 -0400 (0:00:00.071)       0:00:00.099 ***** 
2020-09-08 21:43:14,872 p=99393 u=ganti n=ansible | Using module file /usr/local/lib/python3.7/site-packages/ansible/modules/network/f5/bigip_appsvcs_extension.py
2020-09-08 21:43:14,872 p=99393 u=ganti n=ansible | Pipelining is enabled.
2020-09-08 21:43:14,872 p=99393 u=ganti n=ansible | <localhost> ESTABLISH LOCAL CONNECTION FOR USER: ganti
2020-09-08 21:43:14,873 p=99393 u=ganti n=ansible | <localhost> EXEC /bin/sh -c '/usr/local/opt/python/bin/python3.7 && sleep 0'
2020-09-08 21:43:19,854 p=99384 u=ganti n=ansible | The full traceback is:
  File "/var/folders/94/gcvyc1g9191_npwtrl55hsq54jxlgs/T/ansible_bigip_appsvcs_extension_payload_942ru32v/ansible_bigip_appsvcs_extension_payload.zip/ansible/modules/network/f5/bigip_appsvcs_extension.py", line 542, in main
  File "/var/folders/94/gcvyc1g9191_npwtrl55hsq54jxlgs/T/ansible_bigip_appsvcs_extension_payload_942ru32v/ansible_bigip_appsvcs_extension_payload.zip/ansible/modules/network/f5/bigip_appsvcs_extension.py", line 351, in exec_module
  File "/var/folders/94/gcvyc1g9191_npwtrl55hsq54jxlgs/T/ansible_bigip_appsvcs_extension_payload_942ru32v/ansible_bigip_appsvcs_extension_payload.zip/ansible/modules/network/f5/bigip_appsvcs_extension.py", line 362, in present
  File "/var/folders/94/gcvyc1g9191_npwtrl55hsq54jxlgs/T/ansible_bigip_appsvcs_extension_payload_942ru32v/ansible_bigip_appsvcs_extension_payload.zip/ansible/modules/network/f5/bigip_appsvcs_extension.py", line 461, in exists
  File "/var/folders/94/gcvyc1g9191_npwtrl55hsq54jxlgs/T/ansible_bigip_appsvcs_extension_payload_942ru32v/ansible_bigip_appsvcs_extension_payload.zip/ansible/module_utils/network/f5/bigip.py", line 38, in api
    raise F5ModuleError(err)

2020-09-08 21:43:19,871 p=99384 u=ganti n=ansible | fatal: [localhost -> localhost]: FAILED! => {
    "changed": false,
    "invocation": {
        "module_args": {
            "content": {
                "action": "deploy",
                "class": "AS3",
                "declaration": {
                    "Sample_03": {
                        "A1": {
                            "class": "Application",
                            "service": {
                                "class": "Service_TCP",
                                "pool": "svc_pool",
                                "virtualAddresses": [
                                    "10.0.5.10"
                                ],
                                "virtualPort": 1344
                            },
                            "svc_pool": {
                                "class": "Pool",
                                "members": [
                                    {
                                        "serverAddresses": [
                                            "192.0.5.10",
                                            "192.0.5.11"
                                        ],
                                        "servicePort": 1344
                                    }
                                ],
                                "monitors": [
                                    "tcp"
                                ]
                            }
                        },
                        "class": "Tenant"
                    },
                    "class": "ADC",
                    "id": "789ghi",
                    "label": "Sample 3",
                    "remark": "TCP app",
                    "schemaVersion": "3.20.0"
                },
                "persist": true
            },
            "force": false,
            "provider": {
                "auth_provider": null,
                "password": "VALUE_SPECIFIED_IN_NO_LOG_PARAMETER",
                "server": "54.89.34.114",
                "server_port": 8443,
                "ssh_keyfile": null,
                "timeout": null,
                "transport": "rest",
                "user": "admin",
                "validate_certs": false
            },
            "state": "present",
            "tenants": null
        }
    },
    "msg": "b'<!DOCTYPE HTML PUBLIC \"-//IETF//DTD HTML 2.0//EN\">\\n<html><head>\\n<title>401 Unauthorized</title>\\n</head><body>\\n<h1>Unauthorized</h1>\\n<p>This server could not verify that you\\nare authorized to access the document\\nrequested.  Either you supplied the wrong\\ncredentials (e.g., bad password), or your\\nbrowser doesn\\'t understand how to supply\\nthe credentials required.</p>\\n</body></html>\\n'"
}
2020-09-08 21:43:32,424 p=99384 u=ganti n=ansible | User interrupted execution
